Workbook

Sheet Cover
B2: Project Risk Audit
B5: Capital Deployment & Macro Stress-Testing | Caterpillar (CAT) anchor
B7: Engagement Brief
B8: A manufacturing conglomerate is choosing between automating a domestic plant or outsourcing production. We evaluate the risk-adjusted return under three macro scenarios (Low Growth, Base, High Inflation), using Caterpillar Inc. as the anchor manufacturer to scale realistic cash flow profiles. The audit produces NPV, IRR, and a 2-way sensitivity grid showing how the project ranking shifts with WACC and price elasticity.
B10: Anchor Company
B11: Ticker | C11: CAT (Caterpillar Inc.)
B12: Sector | C12: Industrials - Heavy Equipment / Construction Machinery
B13: Why CAT | C13: Capex-heavy manufacturer with full 5-year history (2014-2018), visible cyclicality
B14: 5-yr Revenue range | C14: $38.5B (2016 trough) - $55.2B (2014 peak)
B15: 5-yr FCF range | C15: $3.6B - $5.6B (more stable than Net Income due to capex discipline)
B17: Methodology
B18: Cash flow forecast | C18: Median 5-yr FCF as steady-state baseline + explicit 1%/2.5%/4% growth scenarios
B19: Risk distribution | C19: Cross-sectional sigma of 5-yr Industrials sector returns (n = ~2,500 ticker-years)
B20: Risk premium | C20: CAPM-style: WACC = rf + beta x ERP; ERP scaled by scenario (0.7x / 1.0x / 2.0x base)
B21: Sensitivity | C21: 2-way data table sweeping WACC (5-15%) x Price Elasticity (-2.0 to 0.0)
B23: How to use this workbook
B24: 1. Inputs | C24: Edit BLUE cells - macro assumptions, project capex, growth rates
B25: 2. WACC_Scenarios | C25: Three named scenarios; toggle Active Scenario to rerun the model
B26: 3. NPV_Engine | C26: Live NPV/IRR for both projects; formulas pull from Inputs + Scenarios
B27: 4. Sensitivity | C27: 2-way data table - shows project winner across WACC x Elasticity grid
B28: 5. Summary | C28: Executive ranking and recommendation
B30: Color coding
B31: BLUE TEXT | C31: Hardcoded inputs - editable
B32: BLACK TEXT | C32: Formulas - do not overwrite
B33: GREEN TEXT | C33: Cross-sheet links
B34: YELLOW BG | C34: Critical assumptions - edit first when stress-testing

Sheet CAT_Statements
B2: Caterpillar (CAT) - 5-Year Financial Panel & Ratio Analysis
B4: Source: Kaggle 200-financial-indicators-of-us-stocks-2014-2018. All values in USD millions unless marked otherwise. Margins displayed as percentages.
B6: Line item ($M unless noted) | C6: 2014 | D6: 2015 | E6: 2016 | F6: 2017 | G6: 2018
B7: INCOME STATEMENT
B8: Revenue | C8: 55184 | D8: 47011 | E8: 38537 | F8: 45462 | G8: 54722
B9: Cost of Revenue | C9: 41342 | D9: 34133 | E9: 28640 | F9: 31906 | G9: 37719
B10: Gross Profit | C10: 13842 | D10: 12878 | E10: 9897 | F10: 13556 | G10: 17003
B11: Operating Income | C11: 3314 | D11: 3785 | E11: 1162 | F11: 4460 | G11: 8293
B12: EBITDA | C12: 6791 | D12: 6981 | E12: 3664 | F12: 7501 | G12: 11015
B13: Net Income | C13: 2452 | D13: 2512 | E13: -67 | F13: 754 | G13: 6147
B15: CASH FLOW
B16: Operating Cash Flow | C16: 8057 | D16: 6699 | E16: 5639 | F16: 5706 | G16: 6558
B17: Free Cash Flow | C17: 5582 | D17: 4198 | E17: 3610 | F17: 4534 | G17: 4578
B18: Capex | C18: -2427.6495 | D18: -2450.2145 | E18: -2031.6646 | F18: -1178.2065 | G18: -1975.6773
B20: BALANCE SHEET
B21: Total Assets | C21: 84681 | D21: 78342 | E21: 74704 | F21: 76962 | G21: 78509
B22: Total Debt | C22: 39285 | D22: 38013 | E22: 36783 | F22: 34878 | G22: 36553
B23: Shareholders Equity | C23: 16746 | D23: 14809 | E23: 13213 | F23: 13766 | G23: 14080
B25: RATIO ANALYSIS
B26: Gross Margin | C26: 0.2508 | D26: 0.2739 | E26: 0.2568 | F26: 0.2982 | G26: 0.3107
B27: EBITDA Margin | C27: 0.123 | D27: 0.148 | E27: 0.095 | F27: 0.165 | G27: 0.201
B28: Net Margin | C28: 0.044 | D28: 0.053 | E28: -0.002 | F28: 0.017 | G28: 0.112
B29: FCF Margin | C29: 0.1012 | D29: 0.0893 | E29: 0.0937 | F29: 0.0997 | G29: 0.0837
B30: Capex / Revenue | C30: 0.044 | D30: 0.0521 | E30: 0.0527 | F30: 0.0259 | G30: 0.0361
B31: Debt / Equity | C31: 2.3459 | D31: 2.5669 | E31: 2.7838 | F31: 2.5336 | G31: 2.5961
B32: Current Ratio | C32: 1.394 | D32: 1.277 | E32: 1.223 | F32: 1.346 | G32: 1.368
B33: Net Debt / EBITDA | C33: 5.78 | D33: 5.45 | E33: 10.04 | F33: 4.65 | G33: 3.32

Sheet FCF_Forecast
B2: 10-Year FCF Forecast (Cyclical-Aware Methodology)
B4: Methodology: A naive linear regression on CAT Revenue produces R^2 = 0.003 (no trend). Standard FP&A practice for cyclical names uses median 5-yr FCF as steady-state baseline plus explicit growth scenarios.
B6: ASSUMPTIONS
B7: Median 5-yr FCF baseline ($M) | C7: =MEDIAN(FCF_2014, FCF_2015, FCF_2016, FCF_2017, FCF_2018) -> 4534
B8: Low Growth assumption | C8: 0.01
B9: Base Case growth | C9: 0.025
B10: High Growth assumption | C10: 0.04
B12: FORECAST ($M)
C13: 2019 | D13: 2020 | E13: 2021 | F13: 2022 | G13: 2023 | H13: 2024 | I13: 2025 | J13: 2026 | K13: 2027 | L13: 2028
B14: Low Growth (1%) | C14: =FCF_Baseline*(1+Growth_Low)^1 -> 4579.34 | D14: =FCF_Baseline*(1+Growth_Low)^2 -> 4625.1334 | E14: =FCF_Baseline*(1+Growth_Low)^3 -> 4671.3847 | F14: =FCF_Baseline*(1+Growth_Low)^4 -> 4718.0986 | G14: =FCF_Baseline*(1+Growth_Low)^5 -> 4765.2796 | H14: =FCF_Baseline*(1+Growth_Low)^6 -> 4812.9324 | I14: =FCF_Baseline*(1+Growth_Low)^7 -> 4861.0617 | J14: =FCF_Baseline*(1+Growth_Low)^8 -> 4909.6723 | K14: =FCF_Baseline*(1+Growth_Low)^9 -> 4958.769 | L14: =FCF_Baseline*(1+Growth_Low)^10 -> 5008.3567
B15: Base Case (2.5%) | C15: =FCF_Baseline*(1+Growth_Base)^1 -> 4647.35 | D15: =FCF_Baseline*(1+Growth_Base)^2 -> 4763.5337 | E15: =FCF_Baseline*(1+Growth_Base)^3 -> 4882.6221 | F15: =FCF_Baseline*(1+Growth_Base)^4 -> 5004.6876 | G15: =FCF_Baseline*(1+Growth_Base)^5 -> 5129.8048 | H15: =FCF_Baseline*(1+Growth_Base)^6 -> 5258.05 | I15: =FCF_Baseline*(1+Growth_Base)^7 -> 5389.5012 | J15: =FCF_Baseline*(1+Growth_Base)^8 -> 5524.2387 | K15: =FCF_Baseline*(1+Growth_Base)^9 -> 5662.3447 | L15: =FCF_Baseline*(1+Growth_Base)^10 -> 5803.9033
B16: High Growth (4%) | C16: =FCF_Baseline*(1+Growth_High)^1 -> 4715.36 | D16: =FCF_Baseline*(1+Growth_High)^2 -> 4903.9744 | E16: =FCF_Baseline*(1+Growth_High)^3 -> 5100.1334 | F16: =FCF_Baseline*(1+Growth_High)^4 -> 5304.1387 | G16: =FCF_Baseline*(1+Growth_High)^5 -> 5516.3043 | H16: =FCF_Baseline*(1+Growth_High)^6 -> 5736.9564 | I16: =FCF_Baseline*(1+Growth_High)^7 -> 5966.4347 | J16: =FCF_Baseline*(1+Growth_High)^8 -> 6205.0921 | K16: =FCF_Baseline*(1+Growth_High)^9 -> 6453.2958 | L16: =FCF_Baseline*(1+Growth_High)^10 -> 6711.4276
B18: Cumulative Base ($M) | C18: =C15 -> 4647.35 | D18: =C18+D15 -> 9410.8838 | E18: =D18+E15 -> 14293.506 | F18: =E18+F15 -> 19298.193 | G18: =F18+G15 -> 24427.998 | H18: =G18+H15 -> 29686.048 | I18: =H18+I15 -> 35075.549 | J18: =I18+J15 -> 40599.788 | K18: =J18+K15 -> 46262.133 | L18: =K18+L15 -> 52066.036

Sheet Project_CF
B2: Project Cash Flow Profiles
B4: Two competing capital projects, each scaled to ~$2B initial capex (Domestic) and ~$0.4B (Outsource). Cash flows reflect typical patterns: heavy capex with delayed ramp-up vs light capex with margin compression by vendor over time.
B6: Year | C6: Y0 | D6: Y1 | E6: Y2 | F6: Y3 | G6: Y4 | H6: Y5 | I6: Y6 | J6: Y7 | K6: Y8 | L6: Y9 | M6: Y10
B7: Domestic Automation ($M) | C7: -2000 | D7: 200 | E7: 350 | F7: 450 | G7: 465.75 | H7: 482.05125 | I7: 498.92304 | J7: 516.38535 | K7: 534.45884 | L7: 553.1649 | M7: 572.52567
B8: Outsourcing ($M) | C8: -400 | D8: 180 | E8: 180 | F8: 180 | G8: 176.4 | H8: 172.872 | I8: 169.41456 | J8: 166.02627 | K8: 162.70574 | L8: 159.45163 | M8: 156.2626
B10: Sum (undiscounted) | C10: =SUM(C7:M7) -> 2623.259 | D10: =SUM(C8:M8) -> 1303.1328
B12: Initial Capex | C12: =ABS(C7) -> 2000 | D12: =ABS(C8) -> 400

Sheet Inputs
B2: Macro & Risk Inputs
B4: 1. Macro & CAPM Inputs
B5: Parameter | C5: Value | D5: Unit | E5: Note
B6: Risk-free rate (rf) | C6: 0.03 | D6: % | E6: 10-yr US Treasury proxy
B7: Equity risk premium (ERP) | C7: 0.045 | D7: % | E7: Long-run US equity premium over Treasuries
B8: Beta proxy | C8: 1 | E8: CAT historical beta is 1.0-1.3; 1.0 conservative
B9: Project horizon | C9: 10 | D9: yrs | E9: Standard capex evaluation horizon
B12: 2. Sector Return Distribution (from notebook)
B13: Statistic | C13: Value | D13: Unit | E13: Source
B14: Sample size (ticker-years) | C14: 2768 | D14: n | E14: Industrials, 5 years
B15: Sector mean return | C15: 0.073579026 | D15: % | E15: Annual return, pooled
B16: Sector sigma (cross-sectional) | C16: 0.47177308 | D16: % | E16: Cross-firm dispersion
B17: Sector variance | C17: 2225.6984 | D17: %^2 | E17: sigma^2
B18: Skewness | C18: 2.115997 | E18: Right-tailed if > 0
B19: Kurtosis (excess) | C19: 17.774737 | E19: Fat tails if > 0

Sheet WACC_Scenarios
B2: WACC Scenarios - 3 Macro States
B4: Three named scenarios are computed via CAPM: WACC = rf + beta x ERP_scenario. The ERP scaling reflects how the sector return distribution narrows in low-growth environments and widens under inflation shocks.
B6: Parameter | C6: Low Growth | D6: Base Case | E6: High Inflation
B7: ERP Scaler | C7: 0.7 | D7: 1 | E7: 2
B8: ERP_scenario | C8: =ERP*C7 -> 0.0315 | D8: =ERP*D7 -> 0.045 | E8: =ERP*E7 -> 0.09
B9: WACC = rf + beta x ERP_scenario | C9: =RF_Rate+Beta*C8 -> 0.0615 | D9: =RF_Rate+Beta*D8 -> 0.075 | E9: =RF_Rate+Beta*E8 -> 0.12
B11: Active Scenario: | C11: 2 | D11: (1=LowG, 2=Base, 3=HighInf)
B12: Active WACC | C12: =INDEX(C9:E9, $C$11) -> 0.075
B14: Rationale | C14: Depressed ERP reflects | D14: Standard CAPM at | E14: Elevated ERP reflects
C15: muted growth expectations | D15: long-run averages | E15: inflation shock pricing

Sheet NPV_Engine
B2: NPV / IRR Engine
B4: Year | C4: Y0 | D4: Y1 | E4: Y2 | F4: Y3 | G4: Y4 | H4: Y5 | I4: Y6 | J4: Y7 | K4: Y8 | L4: Y9 | M4: Y10
B5: Domestic CF (link) | C5: =Project_CF!C7 -> -2000 | D5: =Project_CF!D7 -> 200 | E5: =Project_CF!E7 -> 350 | F5: =Project_CF!F7 -> 450 | G5: =Project_CF!G7 -> 465.75 | H5: =Project_CF!H7 -> 482.05125 | I5: =Project_CF!I7 -> 498.92304 | J5: =Project_CF!J7 -> 516.38535 | ... M5: =Project_CF!M7 -> 572.52567
B6: Discount factor | C6: =1/(1+WACC_Active)^0 -> 1 | D6: =1/(1+WACC_Active)^1 -> 0.93023256 | E6: =1/(1+WACC_Active)^2 -> 0.86533261 | F6: =1/(1+WACC_Active)^3 -> 0.80496057 | G6: =1/(1+WACC_Active)^4 -> 0.74880053 | H6: =1/(1+WACC_Active)^5 -> 0.69655863 | I6: =1/(1+WACC_Active)^6 -> 0.64796152 | J6: =1/(1+WACC_Active)^7 -> 0.6027549 | K6: =1/(1+WACC_Active)^8 -> 0.56070223 | L6: =1/(1+WACC_Active)^9 -> 0.52158347 | M6: =1/(1+WACC_Active)^10 -> 0.48519393
B7: Discounted CF | C7: =C5*C6 -> -2000 | D7: =D5*D6 -> 186.04651 | E7: =E5*E6 -> 302.86641 | F7: =F5*F6 -> 362.23226 | G7: =G5*G6 -> 348.75385 | H7: =H5*H6 -> 335.77696 | I7: =I5*I6 -> 323.28293 | J7: =J5*J6 -> 311.2538 | ... M7: =M5*M6 -> 277.78598
B9: Outsource CF (link) | C9: =Project_CF!C8 -> -400 | D9: =Project_CF!D8 -> 180 | E9: =Project_CF!E8 -> 180 | F9: =Project_CF!F8 -> 180 | G9: =Project_CF!G8 -> 176.4 | H9: =Project_CF!H8 -> 172.872 | I9: =Project_CF!I8 -> 169.41456 | J9: =Project_CF!J8 -> 166.02627 | ... M9: =Project_CF!M8 -> 156.2626
B10: Discounted CF | C10: =C9*C6 -> -400 | D10: =D9*D6 -> 167.44186 | E10: =E9*E6 -> 155.75987 | F10: =F9*F6 -> 144.8929 | G10: =G9*G6 -> 132.08841 | H10: =H9*H6 -> 120.41548 | I10: =I9*I6 -> 109.77412 | J10: =J9*J6 -> 100.07315 | ... M10: =M9*M6 -> 75.817663
B13: DECISION METRICS
C14: Domestic | D14: Outsource
B15: NPV ($M) | C15: =SUM(C7:M7) -> 1036.1926 | D15: =SUM(C10:M10) -> 780.66026
B16: IRR | C16: =IRR(C5:M5) -> 0.1638529 | D16: =IRR(C9:M9) -> 0.42998725
B17: Profitability Index (NPV/Capex) | C17: =C15/ABS(C5) -> 0.51809632 | D17: =D15/ABS(C9) -> 1.9516507
B18: Payback period (years) | C18: =IFERROR(ABS(C5)/AVERAGE(D5:M5), "-") -> 4.3259527 | D18: =IFERROR(ABS(C9)/AVERAGE(D9:M9), "-") -> 2.3486131
B20: Active WACC | C20: =WACC_Active -> 0.075

Sheet Sensitivity
B2: Sensitivity - NPV by WACC x Price Elasticity
B4: This 2-way data table shows the NPV difference (Domestic - Outsource, $M) across WACC and Price Elasticity. Positive (green) cells = Domestic wins. Negative (red) cells = Outsource wins. The cross-over diagonal is the key audit signal.
B6: Elasticity v | WACC > | C6: 0.05 | D6: 0.06 | E6: 0.07 | F6: 0.08 | G6: 0.09 | H6: 0.1 | I6: 0.11 | J6: 0.12 | K6: 0.13 | L6: 0.14 | M6: 0.15
B7: DOMESTIC NPV ($M)
B8: -2 | C8: =Project_CF!C7/(1+C$6)^0+Project_CF!D7*(1+$B8*0.05)/(1+C$6)^1+Project_CF!E7*(1+$B8*0.05)/(1+C$6)^2+Project_CF!F7*(1+$B8*0.05)/(1+C$6)^3+Project_CF!G7*(1+$B8*0.05)/(1+C$6)^4+Project_CF!H7*(1+$B8*0.05)/(1+C$6)^5+Project_CF!I7*(1+$B8*0.05)/(1+C$6)^6+Project_CF!J7*(1+$B8*0.05)/(1+C$6)^7+Project_CF!K7*(1+$B8*0.05)/(1+C$6)^8+Project_CF!L7*(1+$B8*0.05)/(1+C$6)^9+Project_CF!M7*(1+$B8*0.05)/(1+C$6)^10 -> 1119.9627 | D8: =Project_CF!C7/(1+D$6)^0+Project_CF!D7*(1+$B8*0.05)/(1+D$6)^1+Project_CF!E7*(1+$B8*0.05)/(1+D$6)^2+Project_CF!F7*(1+$B8*0.05)/(1+D$6)^3+Project_CF!G7*(1+$B8*0.05)/(1+D$6)^4+Project_CF!H7*(1+$B8*0.05)/(1+D$6)^5+Project_CF!I7*(1+$B8*0.05)/(1+D$6)^6+Project_CF!J7*(1+$B8*0.05)/(1+D$6)^7+Project_CF!K7*(1+$B8*0.05)/(1+D$6)^8+Project_CF!L7*(1+$B8*0.05)/(1+D$6)^9+Project_CF!M7*(1+$B8*0.05)/(1+D$6)^10 -> 956.25405 | E8: =Project_CF!C7/(1+E$6)^0+Project_CF!D7*(1+$B8*0.05)/(1+E$6)^1+Project_CF!E7*(1+$B8*0.05)/(1+E$6)^2+Project_CF!F7*(1+$B8*0.05)/(1+E$6)^3+Project_CF!G7*(1+$B8*0.05)/(1+E$6)^4+Project_CF!H7*(1+$B8*0.05)/(1+E$6)^5+Project_CF!I7*(1+$B8*0.05)/(1+E$6)^6+Project_CF!J7*(1+$B8*0.05)/(1+E$6)^7+Project_CF!K7*(1+$B8*0.05)/(1+E$6)^8+Project_CF!L7*(1+$B8*0.05)/(1+E$6)^9+Project_CF!M7*(1+$B8*0.05)/(1+E$6)^10 -> 804.38931 | F8: =Project_CF!C7/(1+F$6)^0+Project_CF!D7*(1+$B8*0.05)/(1+F$6)^1+Project_CF!E7*(1+$B8*0.05)/(1+F$6)^2+Project_CF!F7*(1+$B8*0.05)/(1+F$6)^3+Project_CF!G7*(1+$B8*0.05)/(1+F$6)^4+Project_CF!H7*(1+$B8*0.05)/(1+F$6)^5+Project_CF!I7*(1+$B8*0.05)/(1+F$6)^6+Project_CF!J7*(1+$B8*0.05)/(1+F$6)^7+Project_CF!K7*(1+$B8*0.05)/(1+F$6)^8+Project_CF!L7*(1+$B8*0.05)/(1+F$6)^9+Project_CF!M7*(1+$B8*0.05)/(1+F$6)^10 -> 663.34144 | G8: =Project_CF!C7/(1+G$6)^0+Project_CF!D7*(1+$B8*0.05)/(1+G$6)^1+Project_CF!E7*(1+$B8*0.05)/(1+G$6)^2+Project_CF!F7*(1+$B8*0.05)/(1+G$6)^3+Project_CF!G7*(1+$B8*0.05)/(1+G$6)^4+Project_CF!H7*(1+$B8*0.05)/(1+G$6)^5+Project_CF!I7*(1+$B8*0.05)/(1+G$6)^6+Project_CF!J7*(1+$B8*0.05)/(1+G$6)^7+Project_CF!K7*(1+$B8*0.05)/(1+G$6)^8+Project_CF!L7*(1+$B8*0.05)/(1+G$6)^9+Project_CF!M7*(1+$B8*0.05)/(1+G$6)^10 -> 532.1846 | H8: =Project_CF!C7/(1+H$6)^0+Project_CF!D7*(1+$B8*0.05)/(1+H$6)^1+Project_CF!E7*(1+$B8*0.05)/(1+H$6)^2+Project_CF!F7*(1+$B8*0.05)/(1+H$6)^3+Project_CF!G7*(1+$B8*0.05)/(1+H$6)^4+Project_CF!H7*(1+$B8*0.05)/(1+H$6)^5+Project_CF!I7*(1+$B8*0.05)/(1+H$6)^6+Project_CF!J7*(1+$B8*0.05)/(1+H$6)^7+Project_CF!K7*(1+$B8*0.05)/(1+H$6)^8+Project_CF!L7*(1+$B8*0.05)/(1+H$6)^9+Project_CF!M7*(1+$B8*0.05)/(1+H$6)^10 -> 410.08316 | I8: =Project_CF!C7/(1+I$6)^0+Project_CF!D7*(1+$B8*0.05)/(1+I$6)^1+Project_CF!E7*(1+$B8*0.05)/(1+I$6)^2+Project_CF!F7*(1+$B8*0.05)/(1+I$6)^3+Project_CF!G7*(1+$B8*0.05)/(1+I$6)^4+Project_CF!H7*(1+$B8*0.05)/(1+I$6)^5+Project_CF!I7*(1+$B8*0.05)/(1+I$6)^6+Project_CF!J7*(1+$B8*0.05)/(1+I$6)^7+Project_CF!K7*(1+$B8*0.05)/(1+I$6)^8+Project_CF!L7*(1+$B8*0.05)/(1+I$6)^9+Project_CF!M7*(1+$B8*0.05)/(1+I$6)^10 -> 296.28196 | J8: =Project_CF!C7/(1+J$6)^0+Project_CF!D7*(1+$B8*0.05)/(1+J$6)^1+Project_CF!E7*(1+$B8*0.05)/(1+J$6)^2+Project_CF!F7*(1+$B8*0.05)/(1+J$6)^3+Project_CF!G7*(1+$B8*0.05)/(1+J$6)^4+Project_CF!H7*(1+$B8*0.05)/(1+J$6)^5+Project_CF!I7*(1+$B8*0.05)/(1+J$6)^6+Project_CF!J7*(1+$B8*0.05)/(1+J$6)^7+Project_CF!K7*(1+$B8*0.05)/(1+J$6)^8+Project_CF!L7*(1+$B8*0.05)/(1+J$6)^9+Project_CF!M7*(1+$B8*0.05)/(1+J$6)^10 -> 190.09773 | K8: =Project_CF!C7/(1+K$6)^0+Project_CF!D7*(1+$B8*0.05)/(1+K$6)^1+Project_CF!E7*(1+$B8*0.05)/(1+K$6)^2+Project_CF!F7*(1+$B8*0.05)/(1+K$6)^3+Project_CF!G7*(1+$B8*0.05)/(1+K$6)^4+Project_CF!H7*(1+$B8*0.05)/(1+K$6)^5+Project_CF!I7*(1+$B8*0.05)/(1+K$6)^6+Project_CF!J7*(1+$B8*0.05)/(1+K$6)^7+Project_CF!K7*(1+$B8*0.05)/(1+K$6)^8+Project_CF!L7*(1+$B8*0.05)/(1+K$6)^9+Project_CF!M7*(1+$B8*0.05)/(1+K$6)^10 -> 90.911495 | L8: =Project_CF!C7/(1+L$6)^0+Project_CF!D7*(1+$B8*0.05)/(1+L$6)^1+Project_CF!E7*(1+$B8*0.05)/(1+L$6)^2+Project_CF!F7*(1+$B8*0.05)/(1+L$6)^3+Project_CF!G7*(1+$B8*0.05)/(1+L$6)^4+Project_CF!H7*(1+$B8*0.05)/(1+L$6)^5+Project_CF!I7*(1+$B8*0.05)/(1+L$6)^6+Project_CF!J7*(1+$B8*0.05)/(1+L$6)^7+Project_CF!K7*(1+$B8*0.05)/(1+L$6)^8+Project_CF!L7*(1+$B8*0.05)/(1+L$6)^9+Project_CF!M7*(1+$B8*0.05)/(1+L$6)^10 -> -1.8381423 | M8: =Project_CF!C7/(1+M$6)^0+Project_CF!D7*(1+$B8*0.05)/(1+M$6)^1+Project_CF!E7*(1+$B8*0.05)/(1+M$6)^2+Project_CF!F7*(1+$B8*0.05)/(1+M$6)^3+Project_CF!G7*(1+$B8*0.05)/(1+M$6)^4+Project_CF!H7*(1+$B8*0.05)/(1+M$6)^5+Project_CF!I7*(1+$B8*0.05)/(1+M$6)^6+Project_CF!J7*(1+$B8*0.05)/(1+M$6)^7+Project_CF!K7*(1+$B8*0.05)/(1+M$6)^8+Project_CF!L7*(1+$B8*0.05)/(1+M$6)^9+Project_CF!M7*(1+$B8*0.05)/(1+M$6)^10 -> -88.660936
B9: -1.5 | C9: =Project_CF!C7/(1+C$6)^0+Project_CF!D7*(1+$B9*0.05)/(1+C$6)^1+Project_CF!E7*(1+$B9*0.05)/(1+C$6)^2+Project_CF!F7*(1+$B9*0.05)/(1+C$6)^3+Project_CF!G7*(1+$B9*0.05)/(1+C$6)^4+Project_CF!H7*(1+$B9*0.05)/(1+C$6)^5+Project_CF!I7*(1+$B9*0.05)/(1+C$6)^6+Project_CF!J7*(1+$B9*0.05)/(1+C$6)^7+Project_CF!K7*(1+$B9*0.05)/(1+C$6)^8+Project_CF!L7*(1+$B9*0.05)/(1+C$6)^9+Project_CF!M7*(1+$B9*0.05)/(1+C$6)^10 -> 1206.6284 | D9: =Project_CF!C7/(1+D$6)^0+Project_CF!D7*(1+$B9*0.05)/(1+D$6)^1+Project_CF!E7*(1+$B9*0.05)/(1+D$6)^2+Project_CF!F7*(1+$B9*0.05)/(1+D$6)^3+Project_CF!G7*(1+$B9*0.05)/(1+D$6)^4+Project_CF!H7*(1+$B9*0.05)/(1+D$6)^5+Project_CF!I7*(1+$B9*0.05)/(1+D$6)^6+Project_CF!J7*(1+$B9*0.05)/(1+D$6)^7+Project_CF!K7*(1+$B9*0.05)/(1+D$6)^8+Project_CF!L7*(1+$B9*0.05)/(1+D$6)^9+Project_CF!M7*(1+$B9*0.05)/(1+D$6)^10 -> 1038.3722 | E9: =Project_CF!C7/(1+E$6)^0+Project_CF!D7*(1+$B9*0.05)/(1+E$6)^1+Project_CF!E7*(1+$B9*0.05)/(1+E$6)^2+Project_CF!F7*(1+$B9*0.05)/(1+E$6)^3+Project_CF!G7*(1+$B9*0.05)/(1+E$6)^4+Project_CF!H7*(1+$B9*0.05)/(1+E$6)^5+Project_CF!I7*(1+$B9*0.05)/(1+E$6)^6+Project_CF!J7*(1+$B9*0.05)/(1+E$6)^7+Project_CF!K7*(1+$B9*0.05)/(1+E$6)^8+Project_CF!L7*(1+$B9*0.05)/(1+E$6)^9+Project_CF!M7*(1+$B9*0.05)/(1+E$6)^10 -> 882.28902 | F9: =Project_CF!C7/(1+F$6)^0+Project_CF!D7*(1+$B9*0.05)/(1+F$6)^1+Project_CF!E7*(1+$B9*0.05)/(1+F$6)^2+Project_CF!F7*(1+$B9*0.05)/(1+F$6)^3+Project_CF!G7*(1+$B9*0.05)/(1+F$6)^4+Project_CF!H7*(1+$B9*0.05)/(1+F$6)^5+Project_CF!I7*(1+$B9*0.05)/(1+F$6)^6+Project_CF!J7*(1+$B9*0.05)/(1+F$6)^7+Project_CF!K7*(1+$B9*0.05)/(1+F$6)^8+Project_CF!L7*(1+$B9*0.05)/(1+F$6)^9+Project_CF!M7*(1+$B9*0.05)/(1+F$6)^10 -> 737.32315 | G9: =Project_CF!C7/(1+G$6)^0+Project_CF!D7*(1+$B9*0.05)/(1+G$6)^1+Project_CF!E7*(1+$B9*0.05)/(1+G$6)^2+Project_CF!F7*(1+$B9*0.05)/(1+G$6)^3+Project_CF!G7*(1+$B9*0.05)/(1+G$6)^4+Project_CF!H7*(1+$B9*0.05)/(1+G$6)^5+Project_CF!I7*(1+$B9*0.05)/(1+G$6)^6+Project_CF!J7*(1+$B9*0.05)/(1+G$6)^7+Project_CF!K7*(1+$B9*0.05)/(1+G$6)^8+Project_CF!L7*(1+$B9*0.05)/(1+G$6)^9+Project_CF!M7*(1+$B9*0.05)/(1+G$6)^10 -> 602.52306 | H9: =Project_CF!C7/(1+H$6)^0+Project_CF!D7*(1+$B9*0.05)/(1+H$6)^1+Project_CF!E7*(1+$B9*0.05)/(1+H$6)^2+Project_CF!F7*(1+$B9*0.05)/(1+H$6)^3+Project_CF!G7*(1+$B9*0.05)/(1+H$6)^4+Project_CF!H7*(1+$B9*0.05)/(1+H$6)^5+Project_CF!I7*(1+$B9*0.05)/(1+H$6)^6+Project_CF!J7*(1+$B9*0.05)/(1+H$6)^7+Project_CF!K7*(1+$B9*0.05)/(1+H$6)^8+Project_CF!L7*(1+$B9*0.05)/(1+H$6)^9+Project_CF!M7*(1+$B9*0.05)/(1+H$6)^10 -> 477.02992 | I9: =Project_CF!C7/(1+I$6)^0+Project_CF!D7*(1+$B9*0.05)/(1+I$6)^1+Project_CF!E7*(1+$B9*0.05)/(1+I$6)^2+Project_CF!F7*(1+$B9*0.05)/(1+I$6)^3+Project_CF!G7*(1+$B9*0.05)/(1+I$6)^4+Project_CF!H7*(1+$B9*0.05)/(1+I$6)^5+Project_CF!I7*(1+$B9*0.05)/(1+I$6)^6+Project_CF!J7*(1+$B9*0.05)/(1+I$6)^7+Project_CF!K7*(1+$B9*0.05)/(1+I$6)^8+Project_CF!L7*(1+$B9*0.05)/(1+I$6)^9+Project_CF!M7*(1+$B9*0.05)/(1+I$6)^10 -> 360.06757 | J9: =Project_CF!C7/(1+J$6)^0+Project_CF!D7*(1+$B9*0.05)/(1+J$6)^1+Project_CF!E7*(1+$B9*0.05)/(1+J$6)^2+Project_CF!F7*(1+$B9*0.05)/(1+J$6)^3+Project_CF!G7*(1+$B9*0.05)/(1+J$6)^4+Project_CF!H7*(1+$B9*0.05)/(1+J$6)^5+Project_CF!I7*(1+$B9*0.05)/(1+J$6)^6+Project_CF!J7*(1+$B9*0.05)/(1+J$6)^7+Project_CF!K7*(1+$B9*0.05)/(1+J$6)^8+Project_CF!L7*(1+$B9*0.05)/(1+J$6)^9+Project_CF!M7*(1+$B9*0.05)/(1+J$6)^10 -> 250.93378 | K9: =Project_CF!C7/(1+K$6)^0+Project_CF!D7*(1+$B9*0.05)/(1+K$6)^1+Project_CF!E7*(1+$B9*0.05)/(1+K$6)^2+Project_CF!F7*(1+$B9*0.05)/(1+K$6)^3+Project_CF!G7*(1+$B9*0.05)/(1+K$6)^4+Project_CF!H7*(1+$B9*0.05)/(1+K$6)^5+Project_CF!I7*(1+$B9*0.05)/(1+K$6)^6+Project_CF!J7*(1+$B9*0.05)/(1+K$6)^7+Project_CF!K7*(1+$B9*0.05)/(1+K$6)^8+Project_CF!L7*(1+$B9*0.05)/(1+K$6)^9+Project_CF!M7*(1+$B9*0.05)/(1+K$6)^10 -> 148.99237 | L9: =Project_CF!C7/(1+L$6)^0+Project_CF!D7*(1+$B9*0.05)/(1+L$6)^1+Project_CF!E7*(1+$B9*0.05)/(1+L$6)^2+Project_CF!F7*(1+$B9*0.05)/(1+L$6)^3+Project_CF!G7*(1+$B9*0.05)/(1+L$6)^4+Project_CF!H7*(1+$B9*0.05)/(1+L$6)^5+Project_CF!I7*(1+$B9*0.05)/(1+L$6)^6+Project_CF!J7*(1+$B9*0.05)/(1+L$6)^7+Project_CF!K7*(1+$B9*0.05)/(1+L$6)^8+Project_CF!L7*(1+$B9*0.05)/(1+L$6)^9+Project_CF!M7*(1+$B9*0.05)/(1+L$6)^10 -> 53.666354 | M9: =Project_CF!C7/(1+M$6)^0+Project_CF!D7*(1+$B9*0.05)/(1+M$6)^1+Project_CF!E7*(1+$B9*0.05)/(1+M$6)^2+Project_CF!F7*(1+$B9*0.05)/(1+M$6)^3+Project_CF!G7*(1+$B9*0.05)/(1+M$6)^4+Project_CF!H7*(1+$B9*0.05)/(1+M$6)^5+Project_CF!I7*(1+$B9*0.05)/(1+M$6)^6+Project_CF!J7*(1+$B9*0.05)/(1+M$6)^7+Project_CF!K7*(1+$B9*0.05)/(1+M$6)^8+Project_CF!L7*(1+$B9*0.05)/(1+M$6)^9+Project_CF!M7*(1+$B9*0.05)/(1+M$6)^10 -> -35.568184
B10: -1 | C10: =Project_CF!C7/(1+C$6)^0+Project_CF!D7*(1+$B10*0.05)/(1+C$6)^1+Project_CF!E7*(1+$B10*0.05)/(1+C$6)^2+Project_CF!F7*(1+$B10*0.05)/(1+C$6)^3+Project_CF!G7*(1+$B10*0.05)/(1+C$6)^4+Project_CF!H7*(1+$B10*0.05)/(1+C$6)^5+Project_CF!I7*(1+$B10*0.05)/(1+C$6)^6+Project_CF!J7*(1+$B10*0.05)/(1+C$6)^7+Project_CF!K7*(1+$B10*0.05)/(1+C$6)^8+Project_CF!L7*(1+$B10*0.05)/(1+C$6)^9+Project_CF!M7*(1+$B10*0.05)/(1+C$6)^10 -> 1293.294 | D10: =Project_CF!C7/(1+D$6)^0+Project_CF!D7*(1+$B10*0.05)/(1+D$6)^1+Project_CF!E7*(1+$B10*0.05)/(1+D$6)^2+Project_CF!F7*(1+$B10*0.05)/(1+D$6)^3+Project_CF!G7*(1+$B10*0.05)/(1+D$6)^4+Project_CF!H7*(1+$B10*0.05)/(1+D$6)^5+Project_CF!I7*(1+$B10*0.05)/(1+D$6)^6+Project_CF!J7*(1+$B10*0.05)/(1+D$6)^7+Project_CF!K7*(1+$B10*0.05)/(1+D$6)^8+Project_CF!L7*(1+$B10*0.05)/(1+D$6)^9+Project_CF!M7*(1+$B10*0.05)/(1+D$6)^10 -> 1120.4904 | E10: =Project_CF!C7/(1+E$6)^0+Project_CF!D7*(1+$B10*0.05)/(1+E$6)^1+Project_CF!E7*(1+$B10*0.05)/(1+E$6)^2+Project_CF!F7*(1+$B10*0.05)/(1+E$6)^3+Project_CF!G7*(1+$B10*0.05)/(1+E$6)^4+Project_CF!H7*(1+$B10*0.05)/(1+E$6)^5+Project_CF!I7*(1+$B10*0.05)/(1+E$6)^6+Project_CF!J7*(1+$B10*0.05)/(1+E$6)^7+Project_CF!K7*(1+$B10*0.05)/(1+E$6)^8+Project_CF!L7*(1+$B10*0.05)/(1+E$6)^9+Project_CF!M7*(1+$B10*0.05)/(1+E$6)^10 -> 960.18872 | F10: =Project_CF!C7/(1+F$6)^0+Project_CF!D7*(1+$B10*0.05)/(1+F$6)^1+Project_CF!E7*(1+$B10*0.05)/(1+F$6)^2+Project_CF!F7*(1+$B10*0.05)/(1+F$6)^3+Project_CF!G7*(1+$B10*0.05)/(1+F$6)^4+Project_CF!H7*(1+$B10*0.05)/(1+F$6)^5+Project_CF!I7*(1+$B10*0.05)/(1+F$6)^6+Project_CF!J7*(1+$B10*0.05)/(1+F$6)^7+Project_CF!K7*(1+$B10*0.05)/(1+F$6)^8+Project_CF!L7*(1+$B10*0.05)/(1+F$6)^9+Project_CF!M7*(1+$B10*0.05)/(1+F$6)^10 -> 811.30485 | G10: =Project_CF!C7/(1+G$6)^0+Project_CF!D7*(1+$B10*0.05)/(1+G$6)^1+Project_CF!E7*(1+$B10*0.05)/(1+G$6)^2+Project_CF!F7*(1+$B10*0.05)/(1+G$6)^3+Project_CF!G7*(1+$B10*0.05)/(1+G$6)^4+Project_CF!H7*(1+$B10*0.05)/(1+G$6)^5+Project_CF!I7*(1+$B10*0.05)/(1+G$6)^6+Project_CF!J7*(1+$B10*0.05)/(1+G$6)^7+Project_CF!K7*(1+$B10*0.05)/(1+G$6)^8+Project_CF!L7*(1+$B10*0.05)/(1+G$6)^9+Project_CF!M7*(1+$B10*0.05)/(1+G$6)^10 -> 672.86152 | H10: =Project_CF!C7/(1+H$6)^0+Project_CF!D7*(1+$B10*0.05)/(1+H$6)^1+Project_CF!E7*(1+$B10*0.05)/(1+H$6)^2+Project_CF!F7*(1+$B10*0.05)/(1+H$6)^3+Project_CF!G7*(1+$B10*0.05)/(1+H$6)^4+Project_CF!H7*(1+$B10*0.05)/(1+H$6)^5+Project_CF!I7*(1+$B10*0.05)/(1+H$6)^6+Project_CF!J7*(1+$B10*0.05)/(1+H$6)^7+Project_CF!K7*(1+$B10*0.05)/(1+H$6)^8+Project_CF!L7*(1+$B10*0.05)/(1+H$6)^9+Project_CF!M7*(1+$B10*0.05)/(1+H$6)^10 -> 543.97667 | I10: =Project_CF!C7/(1+I$6)^0+Project_CF!D7*(1+$B10*0.05)/(1+I$6)^1+Project_CF!E7*(1+$B10*0.05)/(1+I$6)^2+Project_CF!F7*(1+$B10*0.05)/(1+I$6)^3+Project_CF!G7*(1+$B10*0.05)/(1+I$6)^4+Project_CF!H7*(1+$B10*0.05)/(1+I$6)^5+Project_CF!I7*(1+$B10*0.05)/(1+I$6)^6+Project_CF!J7*(1+$B10*0.05)/(1+I$6)^7+Project_CF!K7*(1+$B10*0.05)/(1+I$6)^8+Project_CF!L7*(1+$B10*0.05)/(1+I$6)^9+Project_CF!M7*(1+$B10*0.05)/(1+I$6)^10 -> 423.85319 | J10: =Project_CF!C7/(1+J$6)^0+Project_CF!D7*(1+$B10*0.05)/(1+J$6)^1+Project_CF!E7*(1+$B10*0.05)/(1+J$6)^2+Project_CF!F7*(1+$B10*0.05)/(1+J$6)^3+Project_CF!G7*(1+$B10*0.05)/(1+J$6)^4+Project_CF!H7*(1+$B10*0.05)/(1+J$6)^5+Project_CF!I7*(1+$B10*0.05)/(1+J$6)^6+Project_CF!J7*(1+$B10*0.05)/(1+J$6)^7+Project_CF!K7*(1+$B10*0.05)/(1+J$6)^8+Project_CF!L7*(1+$B10*0.05)/(1+J$6)^9+Project_CF!M7*(1+$B10*0.05)/(1+J$6)^10 -> 311.76983 | K10: =Project_CF!C7/(1+K$6)^0+Project_CF!D7*(1+$B10*0.05)/(1+K$6)^1+Project_CF!E7*(1+$B10*0.05)/(1+K$6)^2+Project_CF!F7*(1+$B10*0.05)/(1+K$6)^3+Project_CF!G7*(1+$B10*0.05)/(1+K$6)^4+Project_CF!H7*(1+$B10*0.05)/(1+K$6)^5+Project_CF!I7*(1+$B10*0.05)/(1+K$6)^6+Project_CF!J7*(1+$B10*0.05)/(1+K$6)^7+Project_CF!K7*(1+$B10*0.05)/(1+K$6)^8+Project_CF!L7*(1+$B10*0.05)/(1+K$6)^9+Project_CF!M7*(1+$B10*0.05)/(1+K$6)^10 -> 207.07324 | L10: =Project_CF!C7/(1+L$6)^0+Project_CF!D7*(1+$B10*0.05)/(1+L$6)^1+Project_CF!E7*(1+$B10*0.05)/(1+L$6)^2+Project_CF!F7*(1+$B10*0.05)/(1+L$6)^3+Project_CF!G7*(1+$B10*0.05)/(1+L$6)^4+Project_CF!H7*(1+$B10*0.05)/(1+L$6)^5+Project_CF!I7*(1+$B10*0.05)/(1+L$6)^6+Project_CF!J7*(1+$B10*0.05)/(1+L$6)^7+Project_CF!K7*(1+$B10*0.05)/(1+L$6)^8+Project_CF!L7*(1+$B10*0.05)/(1+L$6)^9+Project_CF!M7*(1+$B10*0.05)/(1+L$6)^10 -> 109.17085 | M10: =Project_CF!C7/(1+M$6)^0+Project_CF!D7*(1+$B10*0.05)/(1+M$6)^1+Project_CF!E7*(1+$B10*0.05)/(1+M$6)^2+Project_CF!F7*(1+$B10*0.05)/(1+M$6)^3+Project_CF!G7*(1+$B10*0.05)/(1+M$6)^4+Project_CF!H7*(1+$B10*0.05)/(1+M$6)^5+Project_CF!I7*(1+$B10*0.05)/(1+M$6)^6+Project_CF!J7*(1+$B10*0.05)/(1+M$6)^7+Project_CF!K7*(1+$B10*0.05)/(1+M$6)^8+Project_CF!L7*(1+$B10*0.05)/(1+M$6)^9+Project_CF!M7*(1+$B10*0.05)/(1+M$6)^10 -> 17.524568
B11: -0.5 | C11: =Project_CF!C7/(1+C$6)^0+Project_CF!D7*(1+$B11*0.05)/(1+C$6)^1+Project_CF!E7*(1+$B11*0.05)/(1+C$6)^2+Project_CF!F7*(1+$B11*0.05)/(1+C$6)^3+Project_CF!G7*(1+$B11*0.05)/(1+C$6)^4+Project_CF!H7*(1+$B11*0.05)/(1+C$6)^5+Project_CF!I7*(1+$B11*0.05)/(1+C$6)^6+Project_CF!J7*(1+$B11*0.05)/(1+C$6)^7+Project_CF!K7*(1+$B11*0.05)/(1+C$6)^8+Project_CF!L7*(1+$B11*0.05)/(1+C$6)^9+Project_CF!M7*(1+$B11*0.05)/(1+C$6)^10 -> 1379.9596 | D11: =Project_CF!C7/(1+D$6)^0+Project_CF!D7*(1+$B11*0.05)/(1+D$6)^1+Project_CF!E7*(1+$B11*0.05)/(1+D$6)^2+Project_CF!F7*(1+$B11*0.05)/(1+D$6)^3+Project_CF!G7*(1+$B11*0.05)/(1+D$6)^4+Project_CF!H7*(1+$B11*0.05)/(1+D$6)^5+Project_CF!I7*(1+$B11*0.05)/(1+D$6)^6+Project_CF!J7*(1+$B11*0.05)/(1+D$6)^7+Project_CF!K7*(1+$B11*0.05)/(1+D$6)^8+Project_CF!L7*(1+$B11*0.05)/(1+D$6)^9+Project_CF!M7*(1+$B11*0.05)/(1+D$6)^10 -> 1202.6086 | E11: =Project_CF!C7/(1+E$6)^0+Project_CF!D7*(1+$B11*0.05)/(1+E$6)^1+Project_CF!E7*(1+$B11*0.05)/(1+E$6)^2+Project_CF!F7*(1+$B11*0.05)/(1+E$6)^3+Project_CF!G7*(1+$B11*0.05)/(1+E$6)^4+Project_CF!H7*(1+$B11*0.05)/(1+E$6)^5+Project_CF!I7*(1+$B11*0.05)/(1+E$6)^6+Project_CF!J7*(1+$B11*0.05)/(1+E$6)^7+Project_CF!K7*(1+$B11*0.05)/(1+E$6)^8+Project_CF!L7*(1+$B11*0.05)/(1+E$6)^9+Project_CF!M7*(1+$B11*0.05)/(1+E$6)^10 -> 1038.0884 | F11: =Project_CF!C7/(1+F$6)^0+Project_CF!D7*(1+$B11*0.05)/(1+F$6)^1+Project_CF!E7*(1+$B11*0.05)/(1+F$6)^2+Project_CF!F7*(1+$B11*0.05)/(1+F$6)^3+Project_CF!G7*(1+$B11*0.05)/(1+F$6)^4+Project_CF!H7*(1+$B11*0.05)/(1+F$6)^5+Project_CF!I7*(1+$B11*0.05)/(1+F$6)^6+Project_CF!J7*(1+$B11*0.05)/(1+F$6)^7+Project_CF!K7*(1+$B11*0.05)/(1+F$6)^8+Project_CF!L7*(1+$B11*0.05)/(1+F$6)^9+Project_CF!M7*(1+$B11*0.05)/(1+F$6)^10 -> 885.28656 | G11: =Project_CF!C7/(1+G$6)^0+Project_CF!D7*(1+$B11*0.05)/(1+G$6)^1+Project_CF!E7*(1+$B11*0.05)/(1+G$6)^2+Project_CF!F7*(1+$B11*0.05)/(1+G$6)^3+Project_CF!G7*(1+$B11*0.05)/(1+G$6)^4+Project_CF!H7*(1+$B11*0.05)/(1+G$6)^5+Project_CF!I7*(1+$B11*0.05)/(1+G$6)^6+Project_CF!J7*(1+$B11*0.05)/(1+G$6)^7+Project_CF!K7*(1+$B11*0.05)/(1+G$6)^8+Project_CF!L7*(1+$B11*0.05)/(1+G$6)^9+Project_CF!M7*(1+$B11*0.05)/(1+G$6)^10 -> 743.19998 | H11: =Project_CF!C7/(1+H$6)^0+Project_CF!D7*(1+$B11*0.05)/(1+H$6)^1+Project_CF!E7*(1+$B11*0.05)/(1+H$6)^2+Project_CF!F7*(1+$B11*0.05)/(1+H$6)^3+Project_CF!G7*(1+$B11*0.05)/(1+H$6)^4+Project_CF!H7*(1+$B11*0.05)/(1+H$6)^5+Project_CF!I7*(1+$B11*0.05)/(1+H$6)^6+Project_CF!J7*(1+$B11*0.05)/(1+H$6)^7+Project_CF!K7*(1+$B11*0.05)/(1+H$6)^8+Project_CF!L7*(1+$B11*0.05)/(1+H$6)^9+Project_CF!M7*(1+$B11*0.05)/(1+H$6)^10 -> 610.92343 | I11: =Project_CF!C7/(1+I$6)^0+Project_CF!D7*(1+$B11*0.05)/(1+I$6)^1+Project_CF!E7*(1+$B11*0.05)/(1+I$6)^2+Project_CF!F7*(1+$B11*0.05)/(1+I$6)^3+Project_CF!G7*(1+$B11*0.05)/(1+I$6)^4+Project_CF!H7*(1+$B11*0.05)/(1+I$6)^5+Project_CF!I7*(1+$B11*0.05)/(1+I$6)^6+Project_CF!J7*(1+$B11*0.05)/(1+I$6)^7+Project_CF!K7*(1+$B11*0.05)/(1+I$6)^8+Project_CF!L7*(1+$B11*0.05)/(1+I$6)^9+Project_CF!M7*(1+$B11*0.05)/(1+I$6)^10 -> 487.6388 | J11: =Project_CF!C7/(1+J$6)^0+Project_CF!D7*(1+$B11*0.05)/(1+J$6)^1+Project_CF!E7*(1+$B11*0.05)/(1+J$6)^2+Project_CF!F7*(1+$B11*0.05)/(1+J$6)^3+Project_CF!G7*(1+$B11*0.05)/(1+J$6)^4+Project_CF!H7*(1+$B11*0.05)/(1+J$6)^5+Project_CF!I7*(1+$B11*0.05)/(1+J$6)^6+Project_CF!J7*(1+$B11*0.05)/(1+J$6)^7+Project_CF!K7*(1+$B11*0.05)/(1+J$6)^8+Project_CF!L7*(1+$B11*0.05)/(1+J$6)^9+Project_CF!M7*(1+$B11*0.05)/(1+J$6)^10 -> 372.60588 | K11: =Project_CF!C7/(1+K$6)^0+Project_CF!D7*(1+$B11*0.05)/(1+K$6)^1+Project_CF!E7*(1+$B11*0.05)/(1+K$6)^2+Project_CF!F7*(1+$B11*0.05)/(1+K$6)^3+Project_CF!G7*(1+$B11*0.05)/(1+K$6)^4+Project_CF!H7*(1+$B11*0.05)/(1+K$6)^5+Project_CF!I7*(1+$B11*0.05)/(1+K$6)^6+Project_CF!J7*(1+$B11*0.05)/(1+K$6)^7+Project_CF!K7*(1+$B11*0.05)/(1+K$6)^8+Project_CF!L7*(1+$B11*0.05)/(1+K$6)^9+Project_CF!M7*(1+$B11*0.05)/(1+K$6)^10 -> 265.15412 | L11: =Project_CF!C7/(1+L$6)^0+Project_CF!D7*(1+$B11*0.05)/(1+L$6)^1+Project_CF!E7*(1+$B11*0.05)/(1+L$6)^2+Project_CF!F7*(1+$B11*0.05)/(1+L$6)^3+Project_CF!G7*(1+$B11*0.05)/(1+L$6)^4+Project_CF!H7*(1+$B11*0.05)/(1+L$6)^5+Project_CF!I7*(1+$B11*0.05)/(1+L$6)^6+Project_CF!J7*(1+$B11*0.05)/(1+L$6)^7+Project_CF!K7*(1+$B11*0.05)/(1+L$6)^8+Project_CF!L7*(1+$B11*0.05)/(1+L$6)^9+Project_CF!M7*(1+$B11*0.05)/(1+L$6)^10 -> 164.67535 | M11: =Project_CF!C7/(1+M$6)^0+Project_CF!D7*(1+$B11*0.05)/(1+M$6)^1+Project_CF!E7*(1+$B11*0.05)/(1+M$6)^2+Project_CF!F7*(1+$B11*0.05)/(1+M$6)^3+Project_CF!G7*(1+$B11*0.05)/(1+M$6)^4+Project_CF!H7*(1+$B11*0.05)/(1+M$6)^5+Project_CF!I7*(1+$B11*0.05)/(1+M$6)^6+Project_CF!J7*(1+$B11*0.05)/(1+M$6)^7+Project_CF!K7*(1+$B11*0.05)/(1+M$6)^8+Project_CF!L7*(1+$B11*0.05)/(1+M$6)^9+Project_CF!M7*(1+$B11*0.05)/(1+M$6)^10 -> 70.61732
B12: 0 | C12: =Project_CF!C7/(1+C$6)^0+Project_CF!D7*(1+$B12*0.05)/(1+C$6)^1+Project_CF!E7*(1+$B12*0.05)/(1+C$6)^2+Project_CF!F7*(1+$B12*0.05)/(1+C$6)^3+Project_CF!G7*(1+$B12*0.05)/(1+C$6)^4+Project_CF!H7*(1+$B12*0.05)/(1+C$6)^5+Project_CF!I7*(1+$B12*0.05)/(1+C$6)^6+Project_CF!J7*(1+$B12*0.05)/(1+C$6)^7+Project_CF!K7*(1+$B12*0.05)/(1+C$6)^8+Project_CF!L7*(1+$B12*0.05)/(1+C$6)^9+Project_CF!M7*(1+$B12*0.05)/(1+C$6)^10 -> 1466.6253 | D12: =Project_CF!C7/(1+D$6)^0+Project_CF!D7*(1+$B12*0.05)/(1+D$6)^1+Project_CF!E7*(1+$B12*0.05)/(1+D$6)^2+Project_CF!F7*(1+$B12*0.05)/(1+D$6)^3+Project_CF!G7*(1+$B12*0.05)/(1+D$6)^4+Project_CF!H7*(1+$B12*0.05)/(1+D$6)^5+Project_CF!I7*(1+$B12*0.05)/(1+D$6)^6+Project_CF!J7*(1+$B12*0.05)/(1+D$6)^7+Project_CF!K7*(1+$B12*0.05)/(1+D$6)^8+Project_CF!L7*(1+$B12*0.05)/(1+D$6)^9+Project_CF!M7*(1+$B12*0.05)/(1+D$6)^10 -> 1284.7267 | E12: =Project_CF!C7/(1+E$6)^0+Project_CF!D7*(1+$B12*0.05)/(1+E$6)^1+Project_CF!E7*(1+$B12*0.05)/(1+E$6)^2+Project_CF!F7*(1+$B12*0.05)/(1+E$6)^3+Project_CF!G7*(1+$B12*0.05)/(1+E$6)^4+Project_CF!H7*(1+$B12*0.05)/(1+E$6)^5+Project_CF!I7*(1+$B12*0.05)/(1+E$6)^6+Project_CF!J7*(1+$B12*0.05)/(1+E$6)^7+Project_CF!K7*(1+$B12*0.05)/(1+E$6)^8+Project_CF!L7*(1+$B12*0.05)/(1+E$6)^9+Project_CF!M7*(1+$B12*0.05)/(1+E$6)^10 -> 1115.9881 | F12: =Project_CF!C7/(1+F$6)^0+Project_CF!D7*(1+$B12*0.05)/(1+F$6)^1+Project_CF!E7*(1+$B12*0.05)/(1+F$6)^2+Project_CF!F7*(1+$B12*0.05)/(1+F$6)^3+Project_CF!G7*(1+$B12*0.05)/(1+F$6)^4+Project_CF!H7*(1+$B12*0.05)/(1+F$6)^5+Project_CF!I7*(1+$B12*0.05)/(1+F$6)^6+Project_CF!J7*(1+$B12*0.05)/(1+F$6)^7+Project_CF!K7*(1+$B12*0.05)/(1+F$6)^8+Project_CF!L7*(1+$B12*0.05)/(1+F$6)^9+Project_CF!M7*(1+$B12*0.05)/(1+F$6)^10 -> 959.26827 | G12: =Project_CF!C7/(1+G$6)^0+Project_CF!D7*(1+$B12*0.05)/(1+G$6)^1+Project_CF!E7*(1+$B12*0.05)/(1+G$6)^2+Project_CF!F7*(1+$B12*0.05)/(1+G$6)^3+Project_CF!G7*(1+$B12*0.05)/(1+G$6)^4+Project_CF!H7*(1+$B12*0.05)/(1+G$6)^5+Project_CF!I7*(1+$B12*0.05)/(1+G$6)^6+Project_CF!J7*(1+$B12*0.05)/(1+G$6)^7+Project_CF!K7*(1+$B12*0.05)/(1+G$6)^8+Project_CF!L7*(1+$B12*0.05)/(1+G$6)^9+Project_CF!M7*(1+$B12*0.05)/(1+G$6)^10 -> 813.53844 | H12: =Project_CF!C7/(1+H$6)^0+Project_CF!D7*(1+$B12*0.05)/(1+H$6)^1+Project_CF!E7*(1+$B12*0.05)/(1+H$6)^2+Project_CF!F7*(1+$B12*0.05)/(1+H$6)^3+Project_CF!G7*(1+$B12*0.05)/(1+H$6)^4+Project_CF!H7*(1+$B12*0.05)/(1+H$6)^5+Project_CF!I7*(1+$B12*0.05)/(1+H$6)^6+Project_CF!J7*(1+$B12*0.05)/(1+H$6)^7+Project_CF!K7*(1+$B12*0.05)/(1+H$6)^8+Project_CF!L7*(1+$B12*0.05)/(1+H$6)^9+Project_CF!M7*(1+$B12*0.05)/(1+H$6)^10 -> 677.87018 | I12: =Project_CF!C7/(1+I$6)^0+Project_CF!D7*(1+$B12*0.05)/(1+I$6)^1+Project_CF!E7*(1+$B12*0.05)/(1+I$6)^2+Project_CF!F7*(1+$B12*0.05)/(1+I$6)^3+Project_CF!G7*(1+$B12*0.05)/(1+I$6)^4+Project_CF!H7*(1+$B12*0.05)/(1+I$6)^5+Project_CF!I7*(1+$B12*0.05)/(1+I$6)^6+Project_CF!J7*(1+$B12*0.05)/(1+I$6)^7+Project_CF!K7*(1+$B12*0.05)/(1+I$6)^8+Project_CF!L7*(1+$B12*0.05)/(1+I$6)^9+Project_CF!M7*(1+$B12*0.05)/(1+I$6)^10 -> 551.42441 | J12: =Project_CF!C7/(1+J$6)^0+Project_CF!D7*(1+$B12*0.05)/(1+J$6)^1+Project_CF!E7*(1+$B12*0.05)/(1+J$6)^2+Project_CF!F7*(1+$B12*0.05)/(1+J$6)^3+Project_CF!G7*(1+$B12*0.05)/(1+J$6)^4+Project_CF!H7*(1+$B12*0.05)/(1+J$6)^5+Project_CF!I7*(1+$B12*0.05)/(1+J$6)^6+Project_CF!J7*(1+$B12*0.05)/(1+J$6)^7+Project_CF!K7*(1+$B12*0.05)/(1+J$6)^8+Project_CF!L7*(1+$B12*0.05)/(1+J$6)^9+Project_CF!M7*(1+$B12*0.05)/(1+J$6)^10 -> 433.44193 | K12: =Project_CF!C7/(1+K$6)^0+Project_CF!D7*(1+$B12*0.05)/(1+K$6)^1+Project_CF!E7*(1+$B12*0.05)/(1+K$6)^2+Project_CF!F7*(1+$B12*0.05)/(1+K$6)^3+Project_CF!G7*(1+$B12*0.05)/(1+K$6)^4+Project_CF!H7*(1+$B12*0.05)/(1+K$6)^5+Project_CF!I7*(1+$B12*0.05)/(1+K$6)^6+Project_CF!J7*(1+$B12*0.05)/(1+K$6)^7+Project_CF!K7*(1+$B12*0.05)/(1+K$6)^8+Project_CF!L7*(1+$B12*0.05)/(1+K$6)^9+Project_CF!M7*(1+$B12*0.05)/(1+K$6)^10 -> 323.23499 | L12: =Project_CF!C7/(1+L$6)^0+Project_CF!D7*(1+$B12*0.05)/(1+L$6)^1+Project_CF!E7*(1+$B12*0.05)/(1+L$6)^2+Project_CF!F7*(1+$B12*0.05)/(1+L$6)^3+Project_CF!G7*(1+$B12*0.05)/(1+L$6)^4+Project_CF!H7*(1+$B12*0.05)/(1+L$6)^5+Project_CF!I7*(1+$B12*0.05)/(1+L$6)^6+Project_CF!J7*(1+$B12*0.05)/(1+L$6)^7+Project_CF!K7*(1+$B12*0.05)/(1+L$6)^8+Project_CF!L7*(1+$B12*0.05)/(1+L$6)^9+Project_CF!M7*(1+$B12*0.05)/(1+L$6)^10 -> 220.17984 | M12: =Project_CF!C7/(1+M$6)^0+Project_CF!D7*(1+$B12*0.05)/(1+M$6)^1+Project_CF!E7*(1+$B12*0.05)/(1+M$6)^2+Project_CF!F7*(1+$B12*0.05)/(1+M$6)^3+Project_CF!G7*(1+$B12*0.05)/(1+M$6)^4+Project_CF!H7*(1+$B12*0.05)/(1+M$6)^5+Project_CF!I7*(1+$B12*0.05)/(1+M$6)^6+Project_CF!J7*(1+$B12*0.05)/(1+M$6)^7+Project_CF!K7*(1+$B12*0.05)/(1+M$6)^8+Project_CF!L7*(1+$B12*0.05)/(1+M$6)^9+Project_CF!M7*(1+$B12*0.05)/(1+M$6)^10 -> 123.71007
B14: OUTSOURCE NPV ($M) | C14: 0.05 | D14: 0.06 | E14: 0.07 | F14: 0.08 | G14: 0.09 | H14: 0.1 | I14: 0.11 | J14: 0.12 | K14: 0.13 | L14: 0.14 | M14: 0.15
B15: -2 | C15: =Project_CF!C8/(1+C$14)^0+Project_CF!D8*(1+$B15*0.05)/(1+C$14)^1+Project_CF!E8*(1+$B15*0.05)/(1+C$14)^2+Project_CF!F8*(1+$B15*0.05)/(1+C$14)^3+Project_CF!G8*(1+$B15*0.05)/(1+C$14)^4+Project_CF!H8*(1+$B15*0.05)/(1+C$14)^5+Project_CF!I8*(1+$B15*0.05)/(1+C$14)^6+Project_CF!J8*(1+$B15*0.05)/(1+C$14)^7+Project_CF!K8*(1+$B15*0.05)/(1+C$14)^8+Project_CF!L8*(1+$B15*0.05)/(1+C$14)^9+Project_CF!M8*(1+$B15*0.05)/(1+C$14)^10 -> 791.6107 | D15: =Project_CF!C8/(1+D$14)^0+Project_CF!D8*(1+$B15*0.05)/(1+D$14)^1+Project_CF!E8*(1+$B15*0.05)/(1+D$14)^2+Project_CF!F8*(1+$B15*0.05)/(1+D$14)^3+Project_CF!G8*(1+$B15*0.05)/(1+D$14)^4+Project_CF!H8*(1+$B15*0.05)/(1+D$14)^5+Project_CF!I8*(1+$B15*0.05)/(1+D$14)^6+Project_CF!J8*(1+$B15*0.05)/(1+D$14)^7+Project_CF!K8*(1+$B15*0.05)/(1+D$14)^8+Project_CF!L8*(1+$B15*0.05)/(1+D$14)^9+Project_CF!M8*(1+$B15*0.05)/(1+D$14)^10 -> 737.25261 | E15: =Project_CF!C8/(1+E$14)^0+Project_CF!D8*(1+$B15*0.05)/(1+E$14)^1+Project_CF!E8*(1+$B15*0.05)/(1+E$14)^2+Project_CF!F8*(1+$B15*0.05)/(1+E$14)^3+Project_CF!G8*(1+$B15*0.05)/(1+E$14)^4+Project_CF!H8*(1+$B15*0.05)/(1+E$14)^5+Project_CF!I8*(1+$B15*0.05)/(1+E$14)^6+Project_CF!J8*(1+$B15*0.05)/(1+E$14)^7+Project_CF!K8*(1+$B15*0.05)/(1+E$14)^8+Project_CF!L8*(1+$B15*0.05)/(1+E$14)^9+Project_CF!M8*(1+$B15*0.05)/(1+E$14)^10 -> 686.61605 | F15: =Project_CF!C8/(1+F$14)^0+Project_CF!D8*(1+$B15*0.05)/(1+F$14)^1+Project_CF!E8*(1+$B15*0.05)/(1+F$14)^2+Project_CF!F8*(1+$B15*0.05)/(1+F$14)^3+Project_CF!G8*(1+$B15*0.05)/(1+F$14)^4+Project_CF!H8*(1+$B15*0.05)/(1+F$14)^5+Project_CF!I8*(1+$B15*0.05)/(1+F$14)^6+Project_CF!J8*(1+$B15*0.05)/(1+F$14)^7+Project_CF!K8*(1+$B15*0.05)/(1+F$14)^8+Project_CF!L8*(1+$B15*0.05)/(1+F$14)^9+Project_CF!M8*(1+$B15*0.05)/(1+F$14)^10 -> 639.38779 | G15: =Project_CF!C8/(1+G$14)^0+Project_CF!D8*(1+$B15*0.05)/(1+G$14)^1+Project_CF!E8*(1+$B15*0.05)/(1+G$14)^2+Project_CF!F8*(1+$B15*0.05)/(1+G$14)^3+Project_CF!G8*(1+$B15*0.05)/(1+G$14)^4+Project_CF!H8*(1+$B15*0.05)/(1+G$14)^5+Project_CF!I8*(1+$B15*0.05)/(1+G$14)^6+Project_CF!J8*(1+$B15*0.05)/(1+G$14)^7+Project_CF!K8*(1+$B15*0.05)/(1+G$14)^8+Project_CF!L8*(1+$B15*0.05)/(1+G$14)^9+Project_CF!M8*(1+$B15*0.05)/(1+G$14)^10 -> 595.28489 | H15: =Project_CF!C8/(1+H$14)^0+Project_CF!D8*(1+$B15*0.05)/(1+H$14)^1+Project_CF!E8*(1+$B15*0.05)/(1+H$14)^2+Project_CF!F8*(1+$B15*0.05)/(1+H$14)^3+Project_CF!G8*(1+$B15*0.05)/(1+H$14)^4+Project_CF!H8*(1+$B15*0.05)/(1+H$14)^5+Project_CF!I8*(1+$B15*0.05)/(1+H$14)^6+Project_CF!J8*(1+$B15*0.05)/(1+H$14)^7+Project_CF!K8*(1+$B15*0.05)/(1+H$14)^8+Project_CF!L8*(1+$B15*0.05)/(1+H$14)^9+Project_CF!M8*(1+$B15*0.05)/(1+H$14)^10 -> 554.05144 | I15: =Project_CF!C8/(1+I$14)^0+Project_CF!D8*(1+$B15*0.05)/(1+I$14)^1+Project_CF!E8*(1+$B15*0.05)/(1+I$14)^2+Project_CF!F8*(1+$B15*0.05)/(1+I$14)^3+Project_CF!G8*(1+$B15*0.05)/(1+I$14)^4+Project_CF!H8*(1+$B15*0.05)/(1+I$14)^5+Project_CF!I8*(1+$B15*0.05)/(1+I$14)^6+Project_CF!J8*(1+$B15*0.05)/(1+I$14)^7+Project_CF!K8*(1+$B15*0.05)/(1+I$14)^8+Project_CF!L8*(1+$B15*0.05)/(1+I$14)^9+Project_CF!M8*(1+$B15*0.05)/(1+I$14)^10 -> 515.45569 | J15: =Project_CF!C8/(1+J$14)^0+Project_CF!D8*(1+$B15*0.05)/(1+J$14)^1+Project_CF!E8*(1+$B15*0.05)/(1+J$14)^2+Project_CF!F8*(1+$B15*0.05)/(1+J$14)^3+Project_CF!G8*(1+$B15*0.05)/(1+J$14)^4+Project_CF!H8*(1+$B15*0.05)/(1+J$14)^5+Project_CF!I8*(1+$B15*0.05)/(1+J$14)^6+Project_CF!J8*(1+$B15*0.05)/(1+J$14)^7+Project_CF!K8*(1+$B15*0.05)/(1+J$14)^8+Project_CF!L8*(1+$B15*0.05)/(1+J$14)^9+Project_CF!M8*(1+$B15*0.05)/(1+J$14)^10 -> 479.28751 | K15: =Project_CF!C8/(1+K$14)^0+Project_CF!D8*(1+$B15*0.05)/(1+K$14)^1+Project_CF!E8*(1+$B15*0.05)/(1+K$14)^2+Project_CF!F8*(1+$B15*0.05)/(1+K$14)^3+Project_CF!G8*(1+$B15*0.05)/(1+K$14)^4+Project_CF!H8*(1+$B15*0.05)/(1+K$14)^5+Project_CF!I8*(1+$B15*0.05)/(1+K$14)^6+Project_CF!J8*(1+$B15*0.05)/(1+K$14)^7+Project_CF!K8*(1+$B15*0.05)/(1+K$14)^8+Project_CF!L8*(1+$B15*0.05)/(1+K$14)^9+Project_CF!M8*(1+$B15*0.05)/(1+K$14)^10 -> 445.35615 | L15: =Project_CF!C8/(1+L$14)^0+Project_CF!D8*(1+$B15*0.05)/(1+L$14)^1+Project_CF!E8*(1+$B15*0.05)/(1+L$14)^2+Project_CF!F8*(1+$B15*0.05)/(1+L$14)^3+Project_CF!G8*(1+$B15*0.05)/(1+L$14)^4+Project_CF!H8*(1+$B15*0.05)/(1+L$14)^5+Project_CF!I8*(1+$B15*0.05)/(1+L$14)^6+Project_CF!J8*(1+$B15*0.05)/(1+L$14)^7+Project_CF!K8*(1+$B15*0.05)/(1+L$14)^8+Project_CF!L8*(1+$B15*0.05)/(1+L$14)^9+Project_CF!M8*(1+$B15*0.05)/(1+L$14)^10 -> 413.48822 | M15: =Project_CF!C8/(1+M$14)^0+Project_CF!D8*(1+$B15*0.05)/(1+M$14)^1+Project_CF!E8*(1+$B15*0.05)/(1+M$14)^2+Project_CF!F8*(1+$B15*0.05)/(1+M$14)^3+Project_CF!G8*(1+$B15*0.05)/(1+M$14)^4+Project_CF!H8*(1+$B15*0.05)/(1+M$14)^5+Project_CF!I8*(1+$B15*0.05)/(1+M$14)^6+Project_CF!J8*(1+$B15*0.05)/(1+M$14)^7+Project_CF!K8*(1+$B15*0.05)/(1+M$14)^8+Project_CF!L8*(1+$B15*0.05)/(1+M$14)^9+Project_CF!M8*(1+$B15*0.05)/(1+M$14)^10 -> 383.52593
B16: -1.5 | C16: =Project_CF!C8/(1+C$14)^0+Project_CF!D8*(1+$B16*0.05)/(1+C$14)^1+Project_CF!E8*(1+$B16*0.05)/(1+C$14)^2+Project_CF!F8*(1+$B16*0.05)/(1+C$14)^3+Project_CF!G8*(1+$B16*0.05)/(1+C$14)^4+Project_CF!H8*(1+$B16*0.05)/(1+C$14)^5+Project_CF!I8*(1+$B16*0.05)/(1+C$14)^6+Project_CF!J8*(1+$B16*0.05)/(1+C$14)^7+Project_CF!K8*(1+$B16*0.05)/(1+C$14)^8+Project_CF!L8*(1+$B16*0.05)/(1+C$14)^9+Project_CF!M8*(1+$B16*0.05)/(1+C$14)^10 -> 824.711 | D16: =Project_CF!C8/(1+D$14)^0+Project_CF!D8*(1+$B16*0.05)/(1+D$14)^1+Project_CF!E8*(1+$B16*0.05)/(1+D$14)^2+Project_CF!F8*(1+$B16*0.05)/(1+D$14)^3+Project_CF!G8*(1+$B16*0.05)/(1+D$14)^4+Project_CF!H8*(1+$B16*0.05)/(1+D$14)^5+Project_CF!I8*(1+$B16*0.05)/(1+D$14)^6+Project_CF!J8*(1+$B16*0.05)/(1+D$14)^7+Project_CF!K8*(1+$B16*0.05)/(1+D$14)^8+Project_CF!L8*(1+$B16*0.05)/(1+D$14)^9+Project_CF!M8*(1+$B16*0.05)/(1+D$14)^10 -> 768.84296 | E16: =Project_CF!C8/(1+E$14)^0+Project_CF!D8*(1+$B16*0.05)/(1+E$14)^1+Project_CF!E8*(1+$B16*0.05)/(1+E$14)^2+Project_CF!F8*(1+$B16*0.05)/(1+E$14)^3+Project_CF!G8*(1+$B16*0.05)/(1+E$14)^4+Project_CF!H8*(1+$B16*0.05)/(1+E$14)^5+Project_CF!I8*(1+$B16*0.05)/(1+E$14)^6+Project_CF!J8*(1+$B16*0.05)/(1+E$14)^7+Project_CF!K8*(1+$B16*0.05)/(1+E$14)^8+Project_CF!L8*(1+$B16*0.05)/(1+E$14)^9+Project_CF!M8*(1+$B16*0.05)/(1+E$14)^10 -> 716.79983 | F16: =Project_CF!C8/(1+F$14)^0+Project_CF!D8*(1+$B16*0.05)/(1+F$14)^1+Project_CF!E8*(1+$B16*0.05)/(1+F$14)^2+Project_CF!F8*(1+$B16*0.05)/(1+F$14)^3+Project_CF!G8*(1+$B16*0.05)/(1+F$14)^4+Project_CF!H8*(1+$B16*0.05)/(1+F$14)^5+Project_CF!I8*(1+$B16*0.05)/(1+F$14)^6+Project_CF!J8*(1+$B16*0.05)/(1+F$14)^7+Project_CF!K8*(1+$B16*0.05)/(1+F$14)^8+Project_CF!L8*(1+$B16*0.05)/(1+F$14)^9+Project_CF!M8*(1+$B16*0.05)/(1+F$14)^10 -> 668.25968 | G16: =Project_CF!C8/(1+G$14)^0+Project_CF!D8*(1+$B16*0.05)/(1+G$14)^1+Project_CF!E8*(1+$B16*0.05)/(1+G$14)^2+Project_CF!F8*(1+$B16*0.05)/(1+G$14)^3+Project_CF!G8*(1+$B16*0.05)/(1+G$14)^4+Project_CF!H8*(1+$B16*0.05)/(1+G$14)^5+Project_CF!I8*(1+$B16*0.05)/(1+G$14)^6+Project_CF!J8*(1+$B16*0.05)/(1+G$14)^7+Project_CF!K8*(1+$B16*0.05)/(1+G$14)^8+Project_CF!L8*(1+$B16*0.05)/(1+G$14)^9+Project_CF!M8*(1+$B16*0.05)/(1+G$14)^10 -> 622.93169 | H16: =Project_CF!C8/(1+H$14)^0+Project_CF!D8*(1+$B16*0.05)/(1+H$14)^1+Project_CF!E8*(1+$B16*0.05)/(1+H$14)^2+Project_CF!F8*(1+$B16*0.05)/(1+H$14)^3+Project_CF!G8*(1+$B16*0.05)/(1+H$14)^4+Project_CF!H8*(1+$B16*0.05)/(1+H$14)^5+Project_CF!I8*(1+$B16*0.05)/(1+H$14)^6+Project_CF!J8*(1+$B16*0.05)/(1+H$14)^7+Project_CF!K8*(1+$B16*0.05)/(1+H$14)^8+Project_CF!L8*(1+$B16*0.05)/(1+H$14)^9+Project_CF!M8*(1+$B16*0.05)/(1+H$14)^10 -> 580.55287 | I16: =Project_CF!C8/(1+I$14)^0+Project_CF!D8*(1+$B16*0.05)/(1+I$14)^1+Project_CF!E8*(1+$B16*0.05)/(1+I$14)^2+Project_CF!F8*(1+$B16*0.05)/(1+I$14)^3+Project_CF!G8*(1+$B16*0.05)/(1+I$14)^4+Project_CF!H8*(1+$B16*0.05)/(1+I$14)^5+Project_CF!I8*(1+$B16*0.05)/(1+I$14)^6+Project_CF!J8*(1+$B16*0.05)/(1+I$14)^7+Project_CF!K8*(1+$B16*0.05)/(1+I$14)^8+Project_CF!L8*(1+$B16*0.05)/(1+I$14)^9+Project_CF!M8*(1+$B16*0.05)/(1+I$14)^10 -> 540.88501 | J16: =Project_CF!C8/(1+J$14)^0+Project_CF!D8*(1+$B16*0.05)/(1+J$14)^1+Project_CF!E8*(1+$B16*0.05)/(1+J$14)^2+Project_CF!F8*(1+$B16*0.05)/(1+J$14)^3+Project_CF!G8*(1+$B16*0.05)/(1+J$14)^4+Project_CF!H8*(1+$B16*0.05)/(1+J$14)^5+Project_CF!I8*(1+$B16*0.05)/(1+J$14)^6+Project_CF!J8*(1+$B16*0.05)/(1+J$14)^7+Project_CF!K8*(1+$B16*0.05)/(1+J$14)^8+Project_CF!L8*(1+$B16*0.05)/(1+J$14)^9+Project_CF!M8*(1+$B16*0.05)/(1+J$14)^10 -> 503.71216 | K16: =Project_CF!C8/(1+K$14)^0+Project_CF!D8*(1+$B16*0.05)/(1+K$14)^1+Project_CF!E8*(1+$B16*0.05)/(1+K$14)^2+Project_CF!F8*(1+$B16*0.05)/(1+K$14)^3+Project_CF!G8*(1+$B16*0.05)/(1+K$14)^4+Project_CF!H8*(1+$B16*0.05)/(1+K$14)^5+Project_CF!I8*(1+$B16*0.05)/(1+K$14)^6+Project_CF!J8*(1+$B16*0.05)/(1+K$14)^7+Project_CF!K8*(1+$B16*0.05)/(1+K$14)^8+Project_CF!L8*(1+$B16*0.05)/(1+K$14)^9+Project_CF!M8*(1+$B16*0.05)/(1+K$14)^10 -> 468.83826 | L16: =Project_CF!C8/(1+L$14)^0+Project_CF!D8*(1+$B16*0.05)/(1+L$14)^1+Project_CF!E8*(1+$B16*0.05)/(1+L$14)^2+Project_CF!F8*(1+$B16*0.05)/(1+L$14)^3+Project_CF!G8*(1+$B16*0.05)/(1+L$14)^4+Project_CF!H8*(1+$B16*0.05)/(1+L$14)^5+Project_CF!I8*(1+$B16*0.05)/(1+L$14)^6+Project_CF!J8*(1+$B16*0.05)/(1+L$14)^7+Project_CF!K8*(1+$B16*0.05)/(1+L$14)^8+Project_CF!L8*(1+$B16*0.05)/(1+L$14)^9+Project_CF!M8*(1+$B16*0.05)/(1+L$14)^10 -> 436.08511 | M16: =Project_CF!C8/(1+M$14)^0+Project_CF!D8*(1+$B16*0.05)/(1+M$14)^1+Project_CF!E8*(1+$B16*0.05)/(1+M$14)^2+Project_CF!F8*(1+$B16*0.05)/(1+M$14)^3+Project_CF!G8*(1+$B16*0.05)/(1+M$14)^4+Project_CF!H8*(1+$B16*0.05)/(1+M$14)^5+Project_CF!I8*(1+$B16*0.05)/(1+M$14)^6+Project_CF!J8*(1+$B16*0.05)/(1+M$14)^7+Project_CF!K8*(1+$B16*0.05)/(1+M$14)^8+Project_CF!L8*(1+$B16*0.05)/(1+M$14)^9+Project_CF!M8*(1+$B16*0.05)/(1+M$14)^10 -> 405.29054
B17: -1 | C17: =Project_CF!C8/(1+C$14)^0+Project_CF!D8*(1+$B17*0.05)/(1+C$14)^1+Project_CF!E8*(1+$B17*0.05)/(1+C$14)^2+Project_CF!F8*(1+$B17*0.05)/(1+C$14)^3+Project_CF!G8*(1+$B17*0.05)/(1+C$14)^4+Project_CF!H8*(1+$B17*0.05)/(1+C$14)^5+Project_CF!I8*(1+$B17*0.05)/(1+C$14)^6+Project_CF!J8*(1+$B17*0.05)/(1+C$14)^7+Project_CF!K8*(1+$B17*0.05)/(1+C$14)^8+Project_CF!L8*(1+$B17*0.05)/(1+C$14)^9+Project_CF!M8*(1+$B17*0.05)/(1+C$14)^10 -> 857.8113 | D17: =Project_CF!C8/(1+D$14)^0+Project_CF!D8*(1+$B17*0.05)/(1+D$14)^1+Project_CF!E8*(1+$B17*0.05)/(1+D$14)^2+Project_CF!F8*(1+$B17*0.05)/(1+D$14)^3+Project_CF!G8*(1+$B17*0.05)/(1+D$14)^4+Project_CF!H8*(1+$B17*0.05)/(1+D$14)^5+Project_CF!I8*(1+$B17*0.05)/(1+D$14)^6+Project_CF!J8*(1+$B17*0.05)/(1+D$14)^7+Project_CF!K8*(1+$B17*0.05)/(1+D$14)^8+Project_CF!L8*(1+$B17*0.05)/(1+D$14)^9+Project_CF!M8*(1+$B17*0.05)/(1+D$14)^10 -> 800.43331 | E17: =Project_CF!C8/(1+E$14)^0+Project_CF!D8*(1+$B17*0.05)/(1+E$14)^1+Project_CF!E8*(1+$B17*0.05)/(1+E$14)^2+Project_CF!F8*(1+$B17*0.05)/(1+E$14)^3+Project_CF!G8*(1+$B17*0.05)/(1+E$14)^4+Project_CF!H8*(1+$B17*0.05)/(1+E$14)^5+Project_CF!I8*(1+$B17*0.05)/(1+E$14)^6+Project_CF!J8*(1+$B17*0.05)/(1+E$14)^7+Project_CF!K8*(1+$B17*0.05)/(1+E$14)^8+Project_CF!L8*(1+$B17*0.05)/(1+E$14)^9+Project_CF!M8*(1+$B17*0.05)/(1+E$14)^10 -> 746.98361 | F17: =Project_CF!C8/(1+F$14)^0+Project_CF!D8*(1+$B17*0.05)/(1+F$14)^1+Project_CF!E8*(1+$B17*0.05)/(1+F$14)^2+Project_CF!F8*(1+$B17*0.05)/(1+F$14)^3+Project_CF!G8*(1+$B17*0.05)/(1+F$14)^4+Project_CF!H8*(1+$B17*0.05)/(1+F$14)^5+Project_CF!I8*(1+$B17*0.05)/(1+F$14)^6+Project_CF!J8*(1+$B17*0.05)/(1+F$14)^7+Project_CF!K8*(1+$B17*0.05)/(1+F$14)^8+Project_CF!L8*(1+$B17*0.05)/(1+F$14)^9+Project_CF!M8*(1+$B17*0.05)/(1+F$14)^10 -> 697.13156 | G17: =Project_CF!C8/(1+G$14)^0+Project_CF!D8*(1+$B17*0.05)/(1+G$14)^1+Project_CF!E8*(1+$B17*0.05)/(1+G$14)^2+Project_CF!F8*(1+$B17*0.05)/(1+G$14)^3+Project_CF!G8*(1+$B17*0.05)/(1+G$14)^4+Project_CF!H8*(1+$B17*0.05)/(1+G$14)^5+Project_CF!I8*(1+$B17*0.05)/(1+G$14)^6+Project_CF!J8*(1+$B17*0.05)/(1+G$14)^7+Project_CF!K8*(1+$B17*0.05)/(1+G$14)^8+Project_CF!L8*(1+$B17*0.05)/(1+G$14)^9+Project_CF!M8*(1+$B17*0.05)/(1+G$14)^10 -> 650.5785 | H17: =Project_CF!C8/(1+H$14)^0+Project_CF!D8*(1+$B17*0.05)/(1+H$14)^1+Project_CF!E8*(1+$B17*0.05)/(1+H$14)^2+Project_CF!F8*(1+$B17*0.05)/(1+H$14)^3+Project_CF!G8*(1+$B17*0.05)/(1+H$14)^4+Project_CF!H8*(1+$B17*0.05)/(1+H$14)^5+Project_CF!I8*(1+$B17*0.05)/(1+H$14)^6+Project_CF!J8*(1+$B17*0.05)/(1+H$14)^7+Project_CF!K8*(1+$B17*0.05)/(1+H$14)^8+Project_CF!L8*(1+$B17*0.05)/(1+H$14)^9+Project_CF!M8*(1+$B17*0.05)/(1+H$14)^10 -> 607.0543 | I17: =Project_CF!C8/(1+I$14)^0+Project_CF!D8*(1+$B17*0.05)/(1+I$14)^1+Project_CF!E8*(1+$B17*0.05)/(1+I$14)^2+Project_CF!F8*(1+$B17*0.05)/(1+I$14)^3+Project_CF!G8*(1+$B17*0.05)/(1+I$14)^4+Project_CF!H8*(1+$B17*0.05)/(1+I$14)^5+Project_CF!I8*(1+$B17*0.05)/(1+I$14)^6+Project_CF!J8*(1+$B17*0.05)/(1+I$14)^7+Project_CF!K8*(1+$B17*0.05)/(1+I$14)^8+Project_CF!L8*(1+$B17*0.05)/(1+I$14)^9+Project_CF!M8*(1+$B17*0.05)/(1+I$14)^10 -> 566.31434 | J17: =Project_CF!C8/(1+J$14)^0+Project_CF!D8*(1+$B17*0.05)/(1+J$14)^1+Project_CF!E8*(1+$B17*0.05)/(1+J$14)^2+Project_CF!F8*(1+$B17*0.05)/(1+J$14)^3+Project_CF!G8*(1+$B17*0.05)/(1+J$14)^4+Project_CF!H8*(1+$B17*0.05)/(1+J$14)^5+Project_CF!I8*(1+$B17*0.05)/(1+J$14)^6+Project_CF!J8*(1+$B17*0.05)/(1+J$14)^7+Project_CF!K8*(1+$B17*0.05)/(1+J$14)^8+Project_CF!L8*(1+$B17*0.05)/(1+J$14)^9+Project_CF!M8*(1+$B17*0.05)/(1+J$14)^10 -> 528.13682 | K17: =Project_CF!C8/(1+K$14)^0+Project_CF!D8*(1+$B17*0.05)/(1+K$14)^1+Project_CF!E8*(1+$B17*0.05)/(1+K$14)^2+Project_CF!F8*(1+$B17*0.05)/(1+K$14)^3+Project_CF!G8*(1+$B17*0.05)/(1+K$14)^4+Project_CF!H8*(1+$B17*0.05)/(1+K$14)^5+Project_CF!I8*(1+$B17*0.05)/(1+K$14)^6+Project_CF!J8*(1+$B17*0.05)/(1+K$14)^7+Project_CF!K8*(1+$B17*0.05)/(1+K$14)^8+Project_CF!L8*(1+$B17*0.05)/(1+K$14)^9+Project_CF!M8*(1+$B17*0.05)/(1+K$14)^10 -> 492.32038 | L17: =Project_CF!C8/(1+L$14)^0+Project_CF!D8*(1+$B17*0.05)/(1+L$14)^1+Project_CF!E8*(1+$B17*0.05)/(1+L$14)^2+Project_CF!F8*(1+$B17*0.05)/(1+L$14)^3+Project_CF!G8*(1+$B17*0.05)/(1+L$14)^4+Project_CF!H8*(1+$B17*0.05)/(1+L$14)^5+Project_CF!I8*(1+$B17*0.05)/(1+L$14)^6+Project_CF!J8*(1+$B17*0.05)/(1+L$14)^7+Project_CF!K8*(1+$B17*0.05)/(1+L$14)^8+Project_CF!L8*(1+$B17*0.05)/(1+L$14)^9+Project_CF!M8*(1+$B17*0.05)/(1+L$14)^10 -> 458.68201 | M17: =Project_CF!C8/(1+M$14)^0+Project_CF!D8*(1+$B17*0.05)/(1+M$14)^1+Project_CF!E8*(1+$B17*0.05)/(1+M$14)^2+Project_CF!F8*(1+$B17*0.05)/(1+M$14)^3+Project_CF!G8*(1+$B17*0.05)/(1+M$14)^4+Project_CF!H8*(1+$B17*0.05)/(1+M$14)^5+Project_CF!I8*(1+$B17*0.05)/(1+M$14)^6+Project_CF!J8*(1+$B17*0.05)/(1+M$14)^7+Project_CF!K8*(1+$B17*0.05)/(1+M$14)^8+Project_CF!L8*(1+$B17*0.05)/(1+M$14)^9+Project_CF!M8*(1+$B17*0.05)/(1+M$14)^10 -> 427.05515
B18: -0.5 | C18: =Project_CF!C8/(1+C$14)^0+Project_CF!D8*(1+$B18*0.05)/(1+C$14)^1+Project_CF!E8*(1+$B18*0.05)/(1+C$14)^2+Project_CF!F8*(1+$B18*0.05)/(1+C$14)^3+Project_CF!G8*(1+$B18*0.05)/(1+C$14)^4+Project_CF!H8*(1+$B18*0.05)/(1+C$14)^5+Project_CF!I8*(1+$B18*0.05)/(1+C$14)^6+Project_CF!J8*(1+$B18*0.05)/(1+C$14)^7+Project_CF!K8*(1+$B18*0.05)/(1+C$14)^8+Project_CF!L8*(1+$B18*0.05)/(1+C$14)^9+Project_CF!M8*(1+$B18*0.05)/(1+C$14)^10 -> 890.91159 | D18: =Project_CF!C8/(1+D$14)^0+Project_CF!D8*(1+$B18*0.05)/(1+D$14)^1+Project_CF!E8*(1+$B18*0.05)/(1+D$14)^2+Project_CF!F8*(1+$B18*0.05)/(1+D$14)^3+Project_CF!G8*(1+$B18*0.05)/(1+D$14)^4+Project_CF!H8*(1+$B18*0.05)/(1+D$14)^5+Project_CF!I8*(1+$B18*0.05)/(1+D$14)^6+Project_CF!J8*(1+$B18*0.05)/(1+D$14)^7+Project_CF!K8*(1+$B18*0.05)/(1+D$14)^8+Project_CF!L8*(1+$B18*0.05)/(1+D$14)^9+Project_CF!M8*(1+$B18*0.05)/(1+D$14)^10 -> 832.02366 | E18: =Project_CF!C8/(1+E$14)^0+Project_CF!D8*(1+$B18*0.05)/(1+E$14)^1+Project_CF!E8*(1+$B18*0.05)/(1+E$14)^2+Project_CF!F8*(1+$B18*0.05)/(1+E$14)^3+Project_CF!G8*(1+$B18*0.05)/(1+E$14)^4+Project_CF!H8*(1+$B18*0.05)/(1+E$14)^5+Project_CF!I8*(1+$B18*0.05)/(1+E$14)^6+Project_CF!J8*(1+$B18*0.05)/(1+E$14)^7+Project_CF!K8*(1+$B18*0.05)/(1+E$14)^8+Project_CF!L8*(1+$B18*0.05)/(1+E$14)^9+Project_CF!M8*(1+$B18*0.05)/(1+E$14)^10 -> 777.16739 | F18: =Project_CF!C8/(1+F$14)^0+Project_CF!D8*(1+$B18*0.05)/(1+F$14)^1+Project_CF!E8*(1+$B18*0.05)/(1+F$14)^2+Project_CF!F8*(1+$B18*0.05)/(1+F$14)^3+Project_CF!G8*(1+$B18*0.05)/(1+F$14)^4+Project_CF!H8*(1+$B18*0.05)/(1+F$14)^5+Project_CF!I8*(1+$B18*0.05)/(1+F$14)^6+Project_CF!J8*(1+$B18*0.05)/(1+F$14)^7+Project_CF!K8*(1+$B18*0.05)/(1+F$14)^8+Project_CF!L8*(1+$B18*0.05)/(1+F$14)^9+Project_CF!M8*(1+$B18*0.05)/(1+F$14)^10 -> 726.00344 | G18: =Project_CF!C8/(1+G$14)^0+Project_CF!D8*(1+$B18*0.05)/(1+G$14)^1+Project_CF!E8*(1+$B18*0.05)/(1+G$14)^2+Project_CF!F8*(1+$B18*0.05)/(1+G$14)^3+Project_CF!G8*(1+$B18*0.05)/(1+G$14)^4+Project_CF!H8*(1+$B18*0.05)/(1+G$14)^5+Project_CF!I8*(1+$B18*0.05)/(1+G$14)^6+Project_CF!J8*(1+$B18*0.05)/(1+G$14)^7+Project_CF!K8*(1+$B18*0.05)/(1+G$14)^8+Project_CF!L8*(1+$B18*0.05)/(1+G$14)^9+Project_CF!M8*(1+$B18*0.05)/(1+G$14)^10 -> 678.2253 | H18: =Project_CF!C8/(1+H$14)^0+Project_CF!D8*(1+$B18*0.05)/(1+H$14)^1+Project_CF!E8*(1+$B18*0.05)/(1+H$14)^2+Project_CF!F8*(1+$B18*0.05)/(1+H$14)^3+Project_CF!G8*(1+$B18*0.05)/(1+H$14)^4+Project_CF!H8*(1+$B18*0.05)/(1+H$14)^5+Project_CF!I8*(1+$B18*0.05)/(1+H$14)^6+Project_CF!J8*(1+$B18*0.05)/(1+H$14)^7+Project_CF!K8*(1+$B18*0.05)/(1+H$14)^8+Project_CF!L8*(1+$B18*0.05)/(1+H$14)^9+Project_CF!M8*(1+$B18*0.05)/(1+H$14)^10 -> 633.55573 | I18: =Project_CF!C8/(1+I$14)^0+Project_CF!D8*(1+$B18*0.05)/(1+I$14)^1+Project_CF!E8*(1+$B18*0.05)/(1+I$14)^2+Project_CF!F8*(1+$B18*0.05)/(1+I$14)^3+Project_CF!G8*(1+$B18*0.05)/(1+I$14)^4+Project_CF!H8*(1+$B18*0.05)/(1+I$14)^5+Project_CF!I8*(1+$B18*0.05)/(1+I$14)^6+Project_CF!J8*(1+$B18*0.05)/(1+I$14)^7+Project_CF!K8*(1+$B18*0.05)/(1+I$14)^8+Project_CF!L8*(1+$B18*0.05)/(1+I$14)^9+Project_CF!M8*(1+$B18*0.05)/(1+I$14)^10 -> 591.74366 | J18: =Project_CF!C8/(1+J$14)^0+Project_CF!D8*(1+$B18*0.05)/(1+J$14)^1+Project_CF!E8*(1+$B18*0.05)/(1+J$14)^2+Project_CF!F8*(1+$B18*0.05)/(1+J$14)^3+Project_CF!G8*(1+$B18*0.05)/(1+J$14)^4+Project_CF!H8*(1+$B18*0.05)/(1+J$14)^5+Project_CF!I8*(1+$B18*0.05)/(1+J$14)^6+Project_CF!J8*(1+$B18*0.05)/(1+J$14)^7+Project_CF!K8*(1+$B18*0.05)/(1+J$14)^8+Project_CF!L8*(1+$B18*0.05)/(1+J$14)^9+Project_CF!M8*(1+$B18*0.05)/(1+J$14)^10 -> 552.56147 | K18: =Project_CF!C8/(1+K$14)^0+Project_CF!D8*(1+$B18*0.05)/(1+K$14)^1+Project_CF!E8*(1+$B18*0.05)/(1+K$14)^2+Project_CF!F8*(1+$B18*0.05)/(1+K$14)^3+Project_CF!G8*(1+$B18*0.05)/(1+K$14)^4+Project_CF!H8*(1+$B18*0.05)/(1+K$14)^5+Project_CF!I8*(1+$B18*0.05)/(1+K$14)^6+Project_CF!J8*(1+$B18*0.05)/(1+K$14)^7+Project_CF!K8*(1+$B18*0.05)/(1+K$14)^8+Project_CF!L8*(1+$B18*0.05)/(1+K$14)^9+Project_CF!M8*(1+$B18*0.05)/(1+K$14)^10 -> 515.8025 | L18: =Project_CF!C8/(1+L$14)^0+Project_CF!D8*(1+$B18*0.05)/(1+L$14)^1+Project_CF!E8*(1+$B18*0.05)/(1+L$14)^2+Project_CF!F8*(1+$B18*0.05)/(1+L$14)^3+Project_CF!G8*(1+$B18*0.05)/(1+L$14)^4+Project_CF!H8*(1+$B18*0.05)/(1+L$14)^5+Project_CF!I8*(1+$B18*0.05)/(1+L$14)^6+Project_CF!J8*(1+$B18*0.05)/(1+L$14)^7+Project_CF!K8*(1+$B18*0.05)/(1+L$14)^8+Project_CF!L8*(1+$B18*0.05)/(1+L$14)^9+Project_CF!M8*(1+$B18*0.05)/(1+L$14)^10 -> 481.2789 | M18: =Project_CF!C8/(1+M$14)^0+Project_CF!D8*(1+$B18*0.05)/(1+M$14)^1+Project_CF!E8*(1+$B18*0.05)/(1+M$14)^2+Project_CF!F8*(1+$B18*0.05)/(1+M$14)^3+Project_CF!G8*(1+$B18*0.05)/(1+M$14)^4+Project_CF!H8*(1+$B18*0.05)/(1+M$14)^5+Project_CF!I8*(1+$B18*0.05)/(1+M$14)^6+Project_CF!J8*(1+$B18*0.05)/(1+M$14)^7+Project_CF!K8*(1+$B18*0.05)/(1+M$14)^8+Project_CF!L8*(1+$B18*0.05)/(1+M$14)^9+Project_CF!M8*(1+$B18*0.05)/(1+M$14)^10 -> 448.81976
B19: 0 | C19: =Project_CF!C8/(1+C$14)^0+Project_CF!D8*(1+$B19*0.05)/(1+C$14)^1+Project_CF!E8*(1+$B19*0.05)/(1+C$14)^2+Project_CF!F8*(1+$B19*0.05)/(1+C$14)^3+Project_CF!G8*(1+$B19*0.05)/(1+C$14)^4+Project_CF!H8*(1+$B19*0.05)/(1+C$14)^5+Project_CF!I8*(1+$B19*0.05)/(1+C$14)^6+Project_CF!J8*(1+$B19*0.05)/(1+C$14)^7+Project_CF!K8*(1+$B19*0.05)/(1+C$14)^8+Project_CF!L8*(1+$B19*0.05)/(1+C$14)^9+Project_CF!M8*(1+$B19*0.05)/(1+C$14)^10 -> 924.01189 | D19: =Project_CF!C8/(1+D$14)^0+Project_CF!D8*(1+$B19*0.05)/(1+D$14)^1+Project_CF!E8*(1+$B19*0.05)/(1+D$14)^2+Project_CF!F8*(1+$B19*0.05)/(1+D$14)^3+Project_CF!G8*(1+$B19*0.05)/(1+D$14)^4+Project_CF!H8*(1+$B19*0.05)/(1+D$14)^5+Project_CF!I8*(1+$B19*0.05)/(1+D$14)^6+Project_CF!J8*(1+$B19*0.05)/(1+D$14)^7+Project_CF!K8*(1+$B19*0.05)/(1+D$14)^8+Project_CF!L8*(1+$B19*0.05)/(1+D$14)^9+Project_CF!M8*(1+$B19*0.05)/(1+D$14)^10 -> 863.61401 | E19: =Project_CF!C8/(1+E$14)^0+Project_CF!D8*(1+$B19*0.05)/(1+E$14)^1+Project_CF!E8*(1+$B19*0.05)/(1+E$14)^2+Project_CF!F8*(1+$B19*0.05)/(1+E$14)^3+Project_CF!G8*(1+$B19*0.05)/(1+E$14)^4+Project_CF!H8*(1+$B19*0.05)/(1+E$14)^5+Project_CF!I8*(1+$B19*0.05)/(1+E$14)^6+Project_CF!J8*(1+$B19*0.05)/(1+E$14)^7+Project_CF!K8*(1+$B19*0.05)/(1+E$14)^8+Project_CF!L8*(1+$B19*0.05)/(1+E$14)^9+Project_CF!M8*(1+$B19*0.05)/(1+E$14)^10 -> 807.35117 | F19: =Project_CF!C8/(1+F$14)^0+Project_CF!D8*(1+$B19*0.05)/(1+F$14)^1+Project_CF!E8*(1+$B19*0.05)/(1+F$14)^2+Project_CF!F8*(1+$B19*0.05)/(1+F$14)^3+Project_CF!G8*(1+$B19*0.05)/(1+F$14)^4+Project_CF!H8*(1+$B19*0.05)/(1+F$14)^5+Project_CF!I8*(1+$B19*0.05)/(1+F$14)^6+Project_CF!J8*(1+$B19*0.05)/(1+F$14)^7+Project_CF!K8*(1+$B19*0.05)/(1+F$14)^8+Project_CF!L8*(1+$B19*0.05)/(1+F$14)^9+Project_CF!M8*(1+$B19*0.05)/(1+F$14)^10 -> 754.87533 | G19: =Project_CF!C8/(1+G$14)^0+Project_CF!D8*(1+$B19*0.05)/(1+G$14)^1+Project_CF!E8*(1+$B19*0.05)/(1+G$14)^2+Project_CF!F8*(1+$B19*0.05)/(1+G$14)^3+Project_CF!G8*(1+$B19*0.05)/(1+G$14)^4+Project_CF!H8*(1+$B19*0.05)/(1+G$14)^5+Project_CF!I8*(1+$B19*0.05)/(1+G$14)^6+Project_CF!J8*(1+$B19*0.05)/(1+G$14)^7+Project_CF!K8*(1+$B19*0.05)/(1+G$14)^8+Project_CF!L8*(1+$B19*0.05)/(1+G$14)^9+Project_CF!M8*(1+$B19*0.05)/(1+G$14)^10 -> 705.8721 | H19: =Project_CF!C8/(1+H$14)^0+Project_CF!D8*(1+$B19*0.05)/(1+H$14)^1+Project_CF!E8*(1+$B19*0.05)/(1+H$14)^2+Project_CF!F8*(1+$B19*0.05)/(1+H$14)^3+Project_CF!G8*(1+$B19*0.05)/(1+H$14)^4+Project_CF!H8*(1+$B19*0.05)/(1+H$14)^5+Project_CF!I8*(1+$B19*0.05)/(1+H$14)^6+Project_CF!J8*(1+$B19*0.05)/(1+H$14)^7+Project_CF!K8*(1+$B19*0.05)/(1+H$14)^8+Project_CF!L8*(1+$B19*0.05)/(1+H$14)^9+Project_CF!M8*(1+$B19*0.05)/(1+H$14)^10 -> 660.05715 | I19: =Project_CF!C8/(1+I$14)^0+Project_CF!D8*(1+$B19*0.05)/(1+I$14)^1+Project_CF!E8*(1+$B19*0.05)/(1+I$14)^2+Project_CF!F8*(1+$B19*0.05)/(1+I$14)^3+Project_CF!G8*(1+$B19*0.05)/(1+I$14)^4+Project_CF!H8*(1+$B19*0.05)/(1+I$14)^5+Project_CF!I8*(1+$B19*0.05)/(1+I$14)^6+Project_CF!J8*(1+$B19*0.05)/(1+I$14)^7+Project_CF!K8*(1+$B19*0.05)/(1+I$14)^8+Project_CF!L8*(1+$B19*0.05)/(1+I$14)^9+Project_CF!M8*(1+$B19*0.05)/(1+I$14)^10 -> 617.17299 | J19: =Project_CF!C8/(1+J$14)^0+Project_CF!D8*(1+$B19*0.05)/(1+J$14)^1+Project_CF!E8*(1+$B19*0.05)/(1+J$14)^2+Project_CF!F8*(1+$B19*0.05)/(1+J$14)^3+Project_CF!G8*(1+$B19*0.05)/(1+J$14)^4+Project_CF!H8*(1+$B19*0.05)/(1+J$14)^5+Project_CF!I8*(1+$B19*0.05)/(1+J$14)^6+Project_CF!J8*(1+$B19*0.05)/(1+J$14)^7+Project_CF!K8*(1+$B19*0.05)/(1+J$14)^8+Project_CF!L8*(1+$B19*0.05)/(1+J$14)^9+Project_CF!M8*(1+$B19*0.05)/(1+J$14)^10 -> 576.98612 | K19: =Project_CF!C8/(1+K$14)^0+Project_CF!D8*(1+$B19*0.05)/(1+K$14)^1+Project_CF!E8*(1+$B19*0.05)/(1+K$14)^2+Project_CF!F8*(1+$B19*0.05)/(1+K$14)^3+Project_CF!G8*(1+$B19*0.05)/(1+K$14)^4+Project_CF!H8*(1+$B19*0.05)/(1+K$14)^5+Project_CF!I8*(1+$B19*0.05)/(1+K$14)^6+Project_CF!J8*(1+$B19*0.05)/(1+K$14)^7+Project_CF!K8*(1+$B19*0.05)/(1+K$14)^8+Project_CF!L8*(1+$B19*0.05)/(1+K$14)^9+Project_CF!M8*(1+$B19*0.05)/(1+K$14)^10 -> 539.28461 | L19: =Project_CF!C8/(1+L$14)^0+Project_CF!D8*(1+$B19*0.05)/(1+L$14)^1+Project_CF!E8*(1+$B19*0.05)/(1+L$14)^2+Project_CF!F8*(1+$B19*0.05)/(1+L$14)^3+Project_CF!G8*(1+$B19*0.05)/(1+L$14)^4+Project_CF!H8*(1+$B19*0.05)/(1+L$14)^5+Project_CF!I8*(1+$B19*0.05)/(1+L$14)^6+Project_CF!J8*(1+$B19*0.05)/(1+L$14)^7+Project_CF!K8*(1+$B19*0.05)/(1+L$14)^8+Project_CF!L8*(1+$B19*0.05)/(1+L$14)^9+Project_CF!M8*(1+$B19*0.05)/(1+L$14)^10 -> 503.8758 | M19: =Project_CF!C8/(1+M$14)^0+Project_CF!D8*(1+$B19*0.05)/(1+M$14)^1+Project_CF!E8*(1+$B19*0.05)/(1+M$14)^2+Project_CF!F8*(1+$B19*0.05)/(1+M$14)^3+Project_CF!G8*(1+$B19*0.05)/(1+M$14)^4+Project_CF!H8*(1+$B19*0.05)/(1+M$14)^5+Project_CF!I8*(1+$B19*0.05)/(1+M$14)^6+Project_CF!J8*(1+$B19*0.05)/(1+M$14)^7+Project_CF!K8*(1+$B19*0.05)/(1+M$14)^8+Project_CF!L8*(1+$B19*0.05)/(1+M$14)^9+Project_CF!M8*(1+$B19*0.05)/(1+M$14)^10 -> 470.58437
B21: DIFFERENCE: Domestic - Outsource | C21: 0.05 | D21: 0.06 | E21: 0.07 | F21: 0.08 | G21: 0.09 | H21: 0.1 | I21: 0.11 | J21: 0.12 | K21: 0.13 | L21: 0.14 | M21: 0.15
